Workbook
Name carroceria: familias!$D$89:$D$95
Name climatizacion: familias!$D$17:$D$30
Name combustion: familias!$D$31:$D$54
Name frenos: familias!$D$55:$D$60
Name mantenimiento: familias!$D$61:$D$88
Name motor: familias!$D$1:$D$11
Name refrigeracion: familias!$D$12:$D$16

Sheet PEDIDO WEPP
B1: DATOS CLIENTE
B2: Razón Social: | C2: Michael Leffler
B3: CIF: | C3: X-2239443-W
B4: Dirección: | C4: Peones Camineros, Portal A 2 izq. 11158. La barca de Vejer
B5: Dirección envío: | C5: Calle Cruz de la Calzada, 25. P.I. Pelagatos. 11130. Chiclana de la Frontera. Cádiz. España
B6: Teléfono: | C6: +34 640074441
B7: Correo Electrónico: | C7: michael.geonovatek@gmail.com
B8: PEDIDO | I8: Nº | J8: 2025-0001
B9: Descripción | C9: Ref. | D9: Volumen | E9: Cantidad | F9: Unidad | H9: Total | I9: Precio ud | J9: TOTAL | M9: PESO UD | N9: unidad | O9: PESO TOTAL | S9: PALET | T9: PESO | U9: UNIDADES
A10: motor | B10: Tapafugas de Aceite 300 | C10: =IF(B10="-","",VLOOKUP(B10,DATOS!$I$3:$K$200,2,FALSE)) -> 2011-300 | D10: =IF(B10="-","",CONCATENATE(VLOOKUP(C10,DATOS!$J$3:$K$200,2,FALSE)," ml")) -> 300 ml | E10: caja | F10: 2 | G10: =IF(B10="-","",IF(E10="caja",VLOOKUP(B10,DATOS!$I$3:$AC$137,21,FALSE),F10)) -> 24 | H10: =IF(B10="-","",IF(E10="caja",F10*G10,F10)) -> 48 | I10: =IF(B10="-","",VLOOKUP(B10,DATOS!$I$3:$S$138,4,FALSE)) -> 2.8 | J10: =IF(B10="-","",H10*I10) -> 134.4 | M10: =IF(B10="-","",VLOOKUP(B10,DATOS!$I$3:$AF$138,24,FALSE)) -> 0.33 | N10: caja | O10: =IF(H10="",0,M10*H10) -> 15.84 | T10: =1000-T11 -> 626.88 | U10: =1200-U11 -> 27
A11: refrigeracion | B11: Limpia Radiadores | C11: =IF(B11="-","",VLOOKUP(B11,DATOS!$I$3:$K$200,2,FALSE)) -> 2023 | D11: =IF(B11="-","",CONCATENATE(VLOOKUP(C11,DATOS!$J$3:$K$200,2,FALSE)," ml")) -> 400 ml | E11: caja | F11: 1 | G11: =IF(B11="-","",IF(E11="caja",VLOOKUP(B11,DATOS!$I$3:$AC$137,21,FALSE),F11)) -> 24 | H11: =IF(B11="-","",IF(E11="caja",F11*G11,F11)) -> 24 | I11: =IF(B11="-","",VLOOKUP(B11,DATOS!$I$3:$S$138,4,FALSE)) -> 2.75 | J11: =IF(B11="-","",H11*I11) -> 66 | M11: =IF(B11="-","",VLOOKUP(B11,DATOS!$I$3:$AF$138,24,FALSE)) -> 0.44 | O11: =IF(H11="",0,M11*H11) -> 10.56 | T11: =SUM(O10:O123) -> 373.12 | U11: =SUM(H10:H123) -> 1173
A12: climatizacion | B12: Airfresh | C12: =IF(B12="-","",VLOOKUP(B12,DATOS!$I$3:$K$200,2,FALSE)) -> 2025 | D12: =IF(B12="-","",CONCATENATE(VLOOKUP(C12,DATOS!$J$3:$K$200,2,FALSE)," ml")) -> 100 ml | E12: caja | F12: 2 | G12: =IF(B12="-","",IF(E12="caja",VLOOKUP(B12,DATOS!$I$3:$AC$137,21,FALSE),F12)) -> 24 | H12: =IF(B12="-","",IF(E12="caja",F12*G12,F12)) -> 48 | I12: =IF(B12="-","",VLOOKUP(B12,DATOS!$I$3:$S$138,4,FALSE)) -> 3.35 | J12: =IF(B12="-","",H12*I12) -> 160.8 | M12: =IF(B12="-","",VLOOKUP(B12,DATOS!$I$3:$AF$138,24,FALSE)) -> 0.11 | O12: =IF(H12="",0,M12*H12) -> 5.28
A13: carroceria | B13: Pintura de Zinc | C13: =IF(B13="-","",VLOOKUP(B13,DATOS!$I$3:$K$200,2,FALSE)) -> 2090 | D13: =IF(B13="-","",CONCATENATE(VLOOKUP(C13,DATOS!$J$3:$K$200,2,FALSE)," ml")) -> 400 ml | E13: caja | F13: 2 | G13: =IF(B13="-","",IF(E13="caja",VLOOKUP(B13,DATOS!$I$3:$AC$137,21,FALSE),F13)) -> 24 | H13: =IF(B13="-","",IF(E13="caja",F13*G13,F13)) -> 48 | I13: =IF(B13="-","",VLOOKUP(B13,DATOS!$I$3:$S$138,4,FALSE)) -> 3.5 | J13: =IF(B13="-","",H13*I13) -> 168 | M13: =IF(B13="-","",VLOOKUP(B13,DATOS!$I$3:$AF$138,24,FALSE)) -> 0.44 | O13: =IF(H13="",0,M13*H13) -> 21.12
A14: mantenimiento | B14: Lubricante Sintético Adhesivo 400 | C14: =IF(B14="-","",VLOOKUP(B14,DATOS!$I$3:$K$200,2,FALSE)) -> 2040 | D14: =IF(B14="-","",CONCATENATE(VLOOKUP(C14,DATOS!$J$3:$K$200,2,FALSE)," ml")) -> 400 ml | E14: unidad | F14: 6 | G14: =IF(B14="-","",IF(E14="caja",VLOOKUP(B14,DATOS!$I$3:$AC$137,21,FALSE),F14)) -> 6 | H14: =IF(B14="-","",IF(E14="caja",F14*G14,F14)) -> 6 | I14: =IF(B14="-","",VLOOKUP(B14,DATOS!$I$3:$S$138,4,FALSE)) -> 0 | J14: =IF(B14="-","",H14*I14) -> 0 | M14: =IF(B14="-","",VLOOKUP(B14,DATOS!$I$3:$AF$138,24,FALSE)) -> 0.44 | O14: =IF(H14="",0,M14*H14) -> 2.64
A15: motor | B15: Limpiador de Motor SF (sin disolventes) | C15: =IF(B15="-","",VLOOKUP(B15,DATOS!$I$3:$K$200,2,FALSE)) -> 2010 SF | D15: =IF(B15="-","",CONCATENATE(VLOOKUP(C15,DATOS!$J$3:$K$200,2,FALSE)," ml")) -> 300 ml | E15: unidad | F15: 6 | G15: =IF(B15="-","",IF(E15="caja",VLOOKUP(B15,DATOS!$I$3:$AC$137,21,FALSE),F15)) -> 6 | H15: =IF(B15="-","",IF(E15="caja",F15*G15,F15)) -> 6 | I15: =IF(B15="-","",VLOOKUP(B15,DATOS!$I$3:$S$138,4,FALSE)) -> 2.95 | J15: =IF(B15="-","",H15*I15) -> 17.7 | M15: =IF(B15="-","",VLOOKUP(B15,DATOS!$I$3:$AF$138,24,FALSE)) -> 0.33 | N15: caja | O15: =IF(H15="",0,M15*H15) -> 1.98
A16: motor | B16: Limpiador de Motor SF (sin disolventes) | C16: =IF(B16="-","",VLOOKUP(B16,DATOS!$I$3:$K$200,2,FALSE)) -> 2010 SF | D16: =IF(B16="-","",CONCATENATE(VLOOKUP(C16,DATOS!$J$3:$K$200,2,FALSE)," ml")) -> 300 ml | E16: unidad | F16: 6 | G16: =IF(B16="-","",IF(E16="caja",VLOOKUP(B16,DATOS!$I$3:$AC$137,21,FALSE),F16)) -> 6 | H16: =IF(B16="-","",IF(E16="caja",F16*G16,F16)) -> 6 | I16: =IF(B16="-","",VLOOKUP(B16,DATOS!$I$3:$S$138,4,FALSE)) -> 2.95 | J16: =IF(B16="-","",H16*I16) -> 17.7 | M16: =IF(B16="-","",VLOOKUP(B16,DATOS!$I$3:$AF$138,24,FALSE)) -> 0.33 | O16: =IF(H16="",0,M16*H16) -> 1.98
A17: motor | B17: Limpiador de Motor SF (sin disolventes) | C17: =IF(B17="-","",VLOOKUP(B17,DATOS!$I$3:$K$200,2,FALSE)) -> 2010 SF | D17: =IF(B17="-","",CONCATENATE(VLOOKUP(C17,DATOS!$J$3:$K$200,2,FALSE)," ml")) -> 300 ml | E17: unidad | F17: 2 | G17: =IF(B17="-","",IF(E17="caja",VLOOKUP(B17,DATOS!$I$3:$AC$137,21,FALSE),F17)) -> 2 | H17: =IF(B17="-","",IF(E17="caja",F17*G17,F17)) -> 2 | I17: =IF(B17="-","",VLOOKUP(B17,DATOS!$I$3:$S$138,4,FALSE)) -> 2.95 | J17: =IF(B17="-","",H17*I17) -> 5.9 | M17: =IF(B17="-","",VLOOKUP(B17,DATOS!$I$3:$AF$138,24,FALSE)) -> 0.33 | N17: caja | O17: =IF(H17="",0,M17*H17) -> 0.66
A18: motor | B18: Limpiador de Motor SF (sin disolventes) | C18: =IF(B18="-","",VLOOKUP(B18,DATOS!$I$3:$K$200,2,FALSE)) -> 2010 SF | D18: =IF(B18="-","",CONCATENATE(VLOOKUP(C18,DATOS!$J$3:$K$200,2,FALSE)," ml")) -> 300 ml | E18: unidad | F18: 2 | G18: =IF(B18="-","",IF(E18="caja",VLOOKUP(B18,DATOS!$I$3:$AC$137,21,FALSE),F18)) -> 2 | H18: =IF(B18="-","",IF(E18="caja",F18*G18,F18)) -> 2 | I18: =IF(B18="-","",VLOOKUP(B18,DATOS!$I$3:$S$138,4,FALSE)) -> 2.95 | J18: =IF(B18="-","",H18*I18) -> 5.9 | M18: =IF(B18="-","",VLOOKUP(B18,DATOS!$I$3:$AF$138,24,FALSE)) -> 0.33 | O18: =IF(H18="",0,M18*H18) -> 0.66
A19: motor | B19: Limpiador de Motor SF (sin disolventes) | C19: =IF(B19="-","",VLOOKUP(B19,DATOS!$I$3:$K$200,2,FALSE)) -> 2010 SF | D19: =IF(B19="-","",CONCATENATE(VLOOKUP(C19,DATOS!$J$3:$K$200,2,FALSE)," ml")) -> 300 ml | E19: caja | F19: 2 | G19: =IF(B19="-","",IF(E19="caja",VLOOKUP(B19,DATOS!$I$3:$AC$137,21,FALSE),F19)) -> 24 | H19: =IF(B19="-","",IF(E19="caja",F19*G19,F19)) -> 48 | I19: =IF(B19="-","",VLOOKUP(B19,DATOS!$I$3:$S$138,4,FALSE)) -> 2.95 | J19: =IF(B19="-","",H19*I19) -> 141.6 | M19: =IF(B19="-","",VLOOKUP(B19,DATOS!$I$3:$AF$138,24,FALSE)) -> 0.33 | N19: caja | O19: =IF(H19="",0,M19*H19) -> 15.84
A20: motor | B20: Limpiador de Motor SF (sin disolventes) | C20: =IF(B20="-","",VLOOKUP(B20,DATOS!$I$3:$K$200,2,FALSE)) -> 2010 SF | D20: =IF(B20="-","",CONCATENATE(VLOOKUP(C20,DATOS!$J$3:$K$200,2,FALSE)," ml")) -> 300 ml | E20: caja | F20: 1 | G20: =IF(B20="-","",IF(E20="caja",VLOOKUP(B20,DATOS!$I$3:$AC$137,21,FALSE),F20)) -> 24 | H20: =IF(B20="-","",IF(E20="caja",F20*G20,F20)) -> 24 | I20: =IF(B20="-","",VLOOKUP(B20,DATOS!$I$3:$S$138,4,FALSE)) -> 2.95 | J20: =IF(B20="-","",H20*I20) -> 70.8 | M20: =IF(B20="-","",VLOOKUP(B20,DATOS!$I$3:$AF$138,24,FALSE)) -> 0.33 | O20: =IF(H20="",0,M20*H20) -> 7.92
A21: motor | B21: Limpiador de Motor SF (sin disolventes) | C21: =IF(B21="-","",VLOOKUP(B21,DATOS!$I$3:$K$200,2,FALSE)) -> 2010 SF | D21: =IF(B21="-","",CONCATENATE(VLOOKUP(C21,DATOS!$J$3:$K$200,2,FALSE)," ml")) -> 300 ml | E21: unidad | F21: 12 | G21: =IF(B21="-","",IF(E21="caja",VLOOKUP(B21,DATOS!$I$3:$AC$137,21,FALSE),F21)) -> 12 | H21: =IF(B21="-","",IF(E21="caja",F21*G21,F21)) -> 12 | I21: =IF(B21="-","",VLOOKUP(B21,DATOS!$I$3:$S$138,4,FALSE)) -> 2.95 | J21: =IF(B21="-","",H21*I21) -> 35.4 | M21: =IF(B21="-","",VLOOKUP(B21,DATOS!$I$3:$AF$138,24,FALSE)) -> 0.33 | N21: caja | O21: =IF(H21="",0,M21*H21) -> 3.96
A22: motor | B22: Limpiador de Motor SF (sin disolventes) | C22: =IF(B22="-","",VLOOKUP(B22,DATOS!$I$3:$K$200,2,FALSE)) -> 2010 SF | D22: =IF(B22="-","",CONCATENATE(VLOOKUP(C22,DATOS!$J$3:$K$200,2,FALSE)," ml")) -> 300 ml | E22: unidad | F22: 6 | G22: =IF(B22="-","",IF(E22="caja",VLOOKUP(B22,DATOS!$I$3:$AC$137,21,FALSE),F22)) -> 6 | H22: =IF(B22="-","",IF(E22="caja",F22*G22,F22)) -> 6 | I22: =IF(B22="-","",VLOOKUP(B22,DATOS!$I$3:$S$138,4,FALSE)) -> 2.95 | J22: =IF(B22="-","",H22*I22) -> 17.7 | M22: =IF(B22="-","",VLOOKUP(B22,DATOS!$I$3:$AF$138,24,FALSE)) -> 0.33 | O22: =IF(H22="",0,M22*H22) -> 1.98
A23: motor | B23: Limpiador de Motor SF (sin disolventes) | C23: =IF(B23="-","",VLOOKUP(B23,DATOS!$I$3:$K$200,2,FALSE)) -> 2010 SF | D23: =IF(B23="-","",CONCATENATE(VLOOKUP(C23,DATOS!$J$3:$K$200,2,FALSE)," ml")) -> 300 ml | E23: unidad | F23: 2 | G23: =IF(B23="-","",IF(E23="caja",VLOOKUP(B23,DATOS!$I$3:$AC$137,21,FALSE),F23)) -> 2 | H23: =IF(B23="-","",IF(E23="caja",F23*G23,F23)) -> 2 | I23: =IF(B23="-","",VLOOKUP(B23,DATOS!$I$3:$S$138,4,FALSE)) -> 2.95 | J23: =IF(B23="-","",H23*I23) -> 5.9 | M23: =IF(B23="-","",VLOOKUP(B23,DATOS!$I$3:$AF$138,24,FALSE)) -> 0.33 | O23: =IF(H23="",0,M23*H23) -> 0.66
A24: motor | B24: Limpiador de Motor SF (sin disolventes) | C24: =IF(B24="-","",VLOOKUP(B24,DATOS!$I$3:$K$200,2,FALSE)) -> 2010 SF | D24: =IF(B24="-","",CONCATENATE(VLOOKUP(C24,DATOS!$J$3:$K$200,2,FALSE)," ml")) -> 300 ml | E24: unidad | F24: 6 | G24: =IF(B24="-","",IF(E24="caja",VLOOKUP(B24,DATOS!$I$3:$AC$137,21,FALSE),F24)) -> 6 | H24: =IF(B24="-","",IF(E24="caja",F24*G24,F24)) -> 6 | I24: =IF(B24="-","",VLOOKUP(B24,DATOS!$I$3:$S$138,4,FALSE)) -> 2.95 | J24: =IF(B24="-","",H24*I24) -> 17.7 | M24: =IF(B24="-","",VLOOKUP(B24,DATOS!$I$3:$AF$138,24,FALSE)) -> 0.33 | N24: caja | O24: =IF(H24="",0,M24*H24) -> 1.98
A25: motor | B25: Limpiador de Motor SF (sin disolventes) | C25: =IF(B25="-","",VLOOKUP(B25,DATOS!$I$3:$K$200,2,FALSE)) -> 2010 SF | D25: =IF(B25="-","",CONCATENATE(VLOOKUP(C25,DATOS!$J$3:$K$200,2,FALSE)," ml")) -> 300 ml | E25: caja | F25: 1 | G25: =IF(B25="-","",IF(E25="caja",VLOOKUP(B25,DATOS!$I$3:$AC$137,21,FALSE),F25)) -> 24 | H25: =IF(B25="-","",IF(E25="caja",F25*G25,F25)) -> 24 | I25: =IF(B25="-","",VLOOKUP(B25,DATOS!$I$3:$S$138,4,FALSE)) -> 2.95 | J25: =IF(B25="-","",H25*I25) -> 70.8 | M25: =IF(B25="-","",VLOOKUP(B25,DATOS!$I$3:$AF$138,24,FALSE)) -> 0.33 | O25: =IF(H25="",0,M25*H25) -> 7.92
A26: motor | B26: Limpiador de Motor SF (sin disolventes) | C26: =IF(B26="-","",VLOOKUP(B26,DATOS!$I$3:$K$200,2,FALSE)) -> 2010 SF | D26: =IF(B26="-","",CONCATENATE(VLOOKUP(C26,DATOS!$J$3:$K$200,2,FALSE)," ml")) -> 300 ml | E26: unidad | F26: 4 | G26: =IF(B26="-","",IF(E26="caja",VLOOKUP(B26,DATOS!$I$3:$AC$137,21,FALSE),F26)) -> 4 | H26: =IF(B26="-","",IF(E26="caja",F26*G26,F26)) -> 4 | I26: =IF(B26="-","",VLOOKUP(B26,DATOS!$I$3:$S$138,4,FALSE)) -> 2.95 | J26: =IF(B26="-","",H26*I26) -> 11.8 | M26: =IF(B26="-","",VLOOKUP(B26,DATOS!$I$3:$AF$138,24,FALSE)) -> 0.33 | O26: =IF(H26="",0,M26*H26) -> 1.32
A27: motor | B27: Limpiador de Motor SF (sin disolventes) | C27: =IF(B27="-","",VLOOKUP(B27,DATOS!$I$3:$K$200,2,FALSE)) -> 2010 SF | D27: =IF(B27="-","",CONCATENATE(VLOOKUP(C27,DATOS!$J$3:$K$200,2,FALSE)," ml")) -> 300 ml | E27: unidad | F27: 6 | G27: =IF(B27="-","",IF(E27="caja",VLOOKUP(B27,DATOS!$I$3:$AC$137,21,FALSE),F27)) -> 6 | H27: =IF(B27="-","",IF(E27="caja",F27*G27,F27)) -> 6 | I27: =IF(B27="-","",VLOOKUP(B27,DATOS!$I$3:$S$138,4,FALSE)) -> 2.95 | J27: =IF(B27="-","",H27*I27) -> 17.7 | M27: =IF(B27="-","",VLOOKUP(B27,DATOS!$I$3:$AF$138,24,FALSE)) -> 0.33 | O27: =IF(H27="",0,M27*H27) -> 1.98
A28: motor | B28: Limpiador de Motor SF (sin disolventes) | C28: =IF(B28="-","",VLOOKUP(B28,DATOS!$I$3:$K$200,2,FALSE)) -> 2010 SF | D28: =IF(B28="-","",CONCATENATE(VLOOKUP(C28,DATOS!$J$3:$K$200,2,FALSE)," ml")) -> 300 ml | E28: caja | F28: 1 | G28: =IF(B28="-","",IF(E28="caja",VLOOKUP(B28,DATOS!$I$3:$AC$137,21,FALSE),F28)) -> 24 | H28: =IF(B28="-","",IF(E28="caja",F28*G28,F28)) -> 24 | I28: =IF(B28="-","",VLOOKUP(B28,DATOS!$I$3:$S$138,4,FALSE)) -> 2.95 | J28: =IF(B28="-","",H28*I28) -> 70.8 | M28: =IF(B28="-","",VLOOKUP(B28,DATOS!$I$3:$AF$138,24,FALSE)) -> 0.33 | O28: =IF(H28="",0,M28*H28) -> 7.92
A29: motor | B29: Limpiador de Motor SF (sin disolventes) | C29: =IF(B29="-","",VLOOKUP(B29,DATOS!$I$3:$K$200,2,FALSE)) -> 2010 SF | D29: =IF(B29="-","",CONCATENATE(VLOOKUP(C29,DATOS!$J$3:$K$200,2,FALSE)," ml")) -> 300 ml | E29: unidad | F29: 2 | G29: =IF(B29="-","",IF(E29="caja",VLOOKUP(B29,DATOS!$I$3:$AC$137,21,FALSE),F29)) -> 2 | H29: =IF(B29="-","",IF(E29="caja",F29*G29,F29)) -> 2 | I29: =IF(B29="-","",VLOOKUP(B29,DATOS!$I$3:$S$138,4,FALSE)) -> 2.95 | J29: =IF(B29="-","",H29*I29) -> 5.9 | M29: =IF(B29="-","",VLOOKUP(B29,DATOS!$I$3:$AF$138,24,FALSE)) -> 0.33 | N29: caja | O29: =IF(H29="",0,M29*H29) -> 0.66
I30: subtotal | J30: =SUM(J10:J29) -> 1042.5
B32: PEDIDO | I32: Nº | J32: =J8 -> 2025-0001
B33: Descripción | C33: Ref. | D33: Volumen | E33: Cantidad | F33: Unidad | H33: Total | I33: Precio ud | J33: TOTAL
A34: motor | B34: Indicador de Fuga de A/C 250 | C34: =IF(B34="-","",VLOOKUP(B34,DATOS!$I$3:$K$200,2,FALSE)) -> 7050250 | D34: =IF(B34="-","",CONCATENATE(VLOOKUP(C34,DATOS!$J$3:$K$200,2,FALSE)," ml")) -> 250 ml | E34: unidad | F34: 2 | G34: =IF(B34="-","",IF(E34="caja",VLOOKUP(B34,DATOS!$I$3:$AC$137,21,FALSE),F34)) -> 2 | H34: =IF(B34="-","",IF(E34="caja",F34*G34,F34)) -> 2 | I34: =IF(B34="-","",VLOOKUP(B34,DATOS!$I$3:$S$138,4,FALSE)) -> 12.9 | J34: =IF(B34="-","",H34*I34) -> 25.8 | M34: =IF(B34="-","",VLOOKUP(B34,DATOS!$I$3:$AF$138,24,FALSE)) -> 0.275 | N34: caja | O34: =IF(H34="",0,M34*H34) -> 0.55
A35: refrigeracion | B35: Lubricante Universal POE 68 con Indicador UV | C35: =IF(B35="-","",VLOOKUP(B35,DATOS!$I$3:$K$200,2,FALSE)) -> 7035001 | D35: =IF(B35="-","",CONCATENATE(VLOOKUP(C35,DATOS!$J$3:$K$200,2,FALSE)," ml")) -> 1000 ml | E35: unidad | F35: 2 | G35: =IF(B35="-","",IF(E35="caja",VLOOKUP(B35,DATOS!$I$3:$AC$137,21,FALSE),F35)) -> 2 | H35: =IF(B35="-","",IF(E35="caja",F35*G35,F35)) -> 2 | I35: =IF(B35="-","",VLOOKUP(B35,DATOS!$I$3:$S$138,4,FALSE)) -> 13.85 | J35: =IF(B35="-","",H35*I35) -> 27.7 | M35: =IF(B35="-","",VLOOKUP(B35,DATOS!$I$3:$AF$138,24,FALSE)) -> 1.1 | N35: caja | O35: =IF(H35="",0,M35*H35) -> 2.2
A36: climatizacion | B36: Limpiador Intensivo Diésel | C36: =IF(B36="-","",VLOOKUP(B36,DATOS!$I$3:$K$200,2,FALSE)) -> 2030 | D36: =IF(B36="-","",CONCATENATE(VLOOKUP(C36,DATOS!$J$3:$K$200,2,FALSE)," ml")) -> 500 ml | E36: caja | F36: 2 | G36: =IF(B36="-","",IF(E36="caja",VLOOKUP(B36,DATOS!$I$3:$AC$137,21,FALSE),F36)) -> 24 | H36: =IF(B36="-","",IF(E36="caja",F36*G36,F36)) -> 48 | I36: =IF(B36="-","",VLOOKUP(B36,DATOS!$I$3:$S$138,4,FALSE)) -> 3.65 | J36: =IF(B36="-","",H36*I36) -> 175.2 | M36: =IF(B36="-","",VLOOKUP(B36,DATOS!$I$3:$AF$138,24,FALSE)) -> 0.55 | N36: caja | O36: =IF(H36="",0,M36*H36) -> 26.4
A37: carroceria | B37: Limpiador de Admisión de Aire Diésel | C37: =IF(B37="-","",VLOOKUP(B37,DATOS!$I$3:$K$200,2,FALSE)) -> 2130 | D37: =IF(B37="-","",CONCATENATE(VLOOKUP(C37,DATOS!$J$3:$K$200,2,FALSE)," ml")) -> 400 ml | E37: unidad | F37: 2 | G37: =IF(B37="-","",IF(E37="caja",VLOOKUP(B37,DATOS!$I$3:$AC$137,21,FALSE),F37)) -> 2 | H37: =IF(B37="-","",IF(E37="caja",F37*G37,F37)) -> 2 | I37: =IF(B37="-","",VLOOKUP(B37,DATOS!$I$3:$S$138,4,FALSE)) -> 3.95 | J37: =IF(B37="-","",H37*I37) -> 7.9 | M37: =IF(B37="-","",VLOOKUP(B37,DATOS!$I$3:$AF$138,24,FALSE)) -> 0.44 | N37: caja | O37: =IF(H37="",0,M37*H37) -> 0.88
A38: mantenimiento | B38: Limpiador Turbo EGR Aspiración | C38: =IF(B38="-","",VLOOKUP(B38,DATOS!$I$3:$K$200,2,FALSE)) -> 2230 | D38: =IF(B38="-","",CONCATENATE(VLOOKUP(C38,DATOS!$J$3:$K$200,2,FALSE)," ml")) -> 400 ml | E38: unidad | F38: 4 | G38: =IF(B38="-","",IF(E38="caja",VLOOKUP(B38,DATOS!$I$3:$AC$137,21,FALSE),F38)) -> 4 | H38: =IF(B38="-","",IF(E38="caja",F38*G38,F38)) -> 4 | I38: =IF(B38="-","",VLOOKUP(B38,DATOS!$I$3:$S$138,4,FALSE)) -> 6.5 | J38: =IF(B38="-","",H38*I38) -> 26 | M38: =IF(B38="-","",VLOOKUP(B38,DATOS!$I$3:$AF$138,24,FALSE)) -> 0.44 | N38: caja | O38: =IF(H38="",0,M38*H38) -> 1.76
A39: motor | B39: Limpiador de Válvulas de Mariposa y Carburadores | C39: =IF(B39="-","",VLOOKUP(B39,DATOS!$I$3:$K$200,2,FALSE)) -> 2031 | D39: =IF(B39="-","",CONCATENATE(VLOOKUP(C39,DATOS!$J$3:$K$200,2,FALSE)," ml")) -> 400 ml | E39: unidad | F39: 4 | G39: =IF(B39="-","",IF(E39="caja",VLOOKUP(B39,DATOS!$I$3:$AC$137,21,FALSE),F39)) -> 4 | H39: =IF(B39="-","",IF(E39="caja",F39*G39,F39)) -> 4 | I39: =IF(B39="-","",VLOOKUP(B39,DATOS!$I$3:$S$138,4,FALSE)) -> 3.5 | J39: =IF(B39="-","",H39*I39) -> 14 | M39: =IF(B39="-","",VLOOKUP(B39,DATOS!$I$3:$AF$138,24,FALSE)) -> 0.44 | N39: caja | O39: =IF(H39="",0,M39*H39) -> 1.76
A40: motor | B40: Protector Diésel 300 | C40: =IF(B40="-","",VLOOKUP(B40,DATOS!$I$3:$K$200,2,FALSE)) -> 2032-300 | D40: =IF(B40="-","",CONCATENATE(VLOOKUP(C40,DATOS!$J$3:$K$200,2,FALSE)," ml")) -> 300 ml | E40: caja | F40: 2 | G40: =IF(B40="-","",IF(E40="caja",VLOOKUP(B40,DATOS!$I$3:$AC$137,21,FALSE),F40)) -> 24 | H40: =IF(B40="-","",IF(E40="caja",F40*G40,F40)) -> 48 | I40: =IF(B40="-","",VLOOKUP(B40,DATOS!$I$3:$S$138,4,FALSE)) -> 2.55 | J40: =IF(B40="-","",H40*I40) -> 122.4 | M40: =IF(B40="-","",VLOOKUP(B40,DATOS!$I$3:$AF$138,24,FALSE)) -> 0.33 | N40: caja | O40: =IF(H40="",0,M40*H40) -> 15.84
A41: motor | B41: Diésel Limpieza Completa | C41: =IF(B41="-","",VLOOKUP(B41,DATOS!$I$3:$K$200,2,FALSE)) -> 2032+ | D41: =IF(B41="-","",CONCATENATE(VLOOKUP(C41,DATOS!$J$3:$K$200,2,FALSE)," ml")) -> 250 ml | E41: caja | F41: 2 | G41: =IF(B41="-","",IF(E41="caja",VLOOKUP(B41,DATOS!$I$3:$AC$137,21,FALSE),F41)) -> 24 | H41: =IF(B41="-","",IF(E41="caja",F41*G41,F41)) -> 48 | I41: =IF(B41="-","",VLOOKUP(B41,DATOS!$I$3:$S$138,4,FALSE)) -> 3.6 | J41: =IF(B41="-","",H41*I41) -> 172.8 | M41: =IF(B41="-","",VLOOKUP(B41,DATOS!$I$3:$AF$138,24,FALSE)) -> 0.275 | N41: caja | O41: =IF(H41="",0,M41*H41) -> 13.2
...

Sheet PEDIDO WEPP ALEMAN
B1: DATOS CLIENTE
B2: Razón Social: | D2: ='PEDIDO WEPP'!C2 -> Michael Leffler
B3: CIF: | D3: ='PEDIDO WEPP'!C3 -> X-2239443-W
B4: Dirección: | D4: ='PEDIDO WEPP'!C4 -> Peones Camineros, Portal A 2 izq. 11158. La barca de Vejer
B5: Dirección envío: | D5: ='PEDIDO WEPP'!C5 -> Calle Cruz de la Calzada, 25. P.I. Pelagatos. 11130. Chiclana de la Frontera. Cádiz. España
B6: Teléfono: | D6: ='PEDIDO WEPP'!C6 -> +34 640074441
B7: Correo Electrónico: | D7: ='PEDIDO WEPP'!C7 -> michael.geonovatek@gmail.com
B8: PEDIDO | I8: Nº | J8: ='PEDIDO WEPP'!J8 -> 2025-0001
B9: Ref. | C9: PRODUKT | D9: Volumen | G9: STÜCK | H9: Total | I9: Einzelpreis | J9: TOTAL
B10: ='PEDIDO WEPP'!C10 -> 2011-300 | C10: =IF(B10="","",VLOOKUP(B10,DATOS!$F$3:$H$139,3,FALSE)) -> Ölstopp Additiv | D10: =IF(B10="","",'PEDIDO WEPP'!D10) -> 300 ml | E10: =IF(B10="","",'PEDIDO WEPP'!E10) -> caja | F10: =IF(E10="CAJA","KISTE",IF(E10="unidad","STÜCK","")) -> KISTE | G10: =IF(B10="","",'PEDIDO WEPP'!F10) -> 2 | H10: =IF(B10="","",'PEDIDO WEPP'!H10) -> 48 | I10: =IF(B10="","",'PEDIDO WEPP'!I10) -> 2.8 | J10: =IF(B10="","",'PEDIDO WEPP'!J10) -> 134.4
B11: ='PEDIDO WEPP'!C11 -> 2023 | C11: =IF(B11="","",VLOOKUP(B11,DATOS!$F$3:$H$139,3,FALSE)) -> Kühlerreinigung | D11: =IF(B11="","",'PEDIDO WEPP'!D11) -> 400 ml | E11: =IF(B11="","",'PEDIDO WEPP'!E11) -> caja | F11: =IF(E11="CAJA","KISTE",IF(E11="unidad","STÜCK","")) -> KISTE | G11: =IF(B11="","",'PEDIDO WEPP'!F11) -> 1 | H11: =IF(B11="","",'PEDIDO WEPP'!H11) -> 24 | I11: =IF(B11="","",'PEDIDO WEPP'!I11) -> 2.75 | J11: =IF(B11="","",'PEDIDO WEPP'!J11) -> 66
B12: ='PEDIDO WEPP'!C12 -> 2025 | C12: =IF(B12="","",VLOOKUP(B12,DATOS!$F$3:$H$139,3,FALSE)) -> Airfresh | D12: =IF(B12="","",'PEDIDO WEPP'!D12) -> 100 ml | E12: =IF(B12="","",'PEDIDO WEPP'!E12) -> caja | F12: =IF(E12="CAJA","KISTE",IF(E12="unidad","STÜCK","")) -> KISTE | G12: =IF(B12="","",'PEDIDO WEPP'!F12) -> 2 | H12: =IF(B12="","",'PEDIDO WEPP'!H12) -> 48 | I12: =IF(B12="","",'PEDIDO WEPP'!I12) -> 3.35 | J12: =IF(B12="","",'PEDIDO WEPP'!J12) -> 160.8
B13: ='PEDIDO WEPP'!C13 -> 2090 | C13: =IF(B13="","",VLOOKUP(B13,DATOS!$F$3:$H$139,3,FALSE)) -> Metallschutz Spray | D13: =IF(B13="","",'PEDIDO WEPP'!D13) -> 400 ml | E13: =IF(B13="","",'PEDIDO WEPP'!E13) -> caja | F13: =IF(E13="CAJA","KISTE",IF(E13="unidad","STÜCK","")) -> KISTE | G13: =IF(B13="","",'PEDIDO WEPP'!F13) -> 2 | H13: =IF(B13="","",'PEDIDO WEPP'!H13) -> 48 | I13: =IF(B13="","",'PEDIDO WEPP'!I13) -> 3.5 | J13: =IF(B13="","",'PEDIDO WEPP'!J13) -> 168
B14: ='PEDIDO WEPP'!C14 -> 2040 | C14: =IF(B14="","",VLOOKUP(B14,DATOS!$F$3:$H$139,3,FALSE)) -> Haftsynthese | D14: =IF(B14="","",'PEDIDO WEPP'!D14) -> 400 ml | E14: =IF(B14="","",'PEDIDO WEPP'!E14) -> unidad | F14: =IF(E14="CAJA","KISTE",IF(E14="unidad","STÜCK","")) -> STÜCK | G14: =IF(B14="","",'PEDIDO WEPP'!F14) -> 6 | H14: =IF(B14="","",'PEDIDO WEPP'!H14) -> 6 | I14: =IF(B14="","",'PEDIDO WEPP'!I14) -> 0 | J14: =IF(B14="","",'PEDIDO WEPP'!J14) -> 0
B15: ='PEDIDO WEPP'!C15 -> 2010 SF | C15: =IF(B15="","",VLOOKUP(B15,DATOS!$F$3:$H$139,3,FALSE)) -> Motor System Reiniger (Lösungsmittelfrei) | D15: =IF(B15="","",'PEDIDO WEPP'!D15) -> 300 ml | E15: =IF(B15="","",'PEDIDO WEPP'!E15) -> unidad | F15: =IF(E15="CAJA","KISTE",IF(E15="unidad","STÜCK","")) -> STÜCK | G15: =IF(B15="","",'PEDIDO WEPP'!F15) -> 6 | H15: =IF(B15="","",'PEDIDO WEPP'!H15) -> 6 | I15: =IF(B15="","",'PEDIDO WEPP'!I15) -> 2.95 | J15: =IF(B15="","",'PEDIDO WEPP'!J15) -> 17.7
B16: ='PEDIDO WEPP'!C16 -> 2010 SF | C16: =IF(B16="","",VLOOKUP(B16,DATOS!$F$3:$H$139,3,FALSE)) -> Motor System Reiniger (Lösungsmittelfrei) | D16: =IF(B16="","",'PEDIDO WEPP'!D16) -> 300 ml | E16: =IF(B16="","",'PEDIDO WEPP'!E16) -> unidad | F16: =IF(E16="CAJA","KISTE",IF(E16="unidad","STÜCK","")) -> STÜCK | G16: =IF(B16="","",'PEDIDO WEPP'!F16) -> 6 | H16: =IF(B16="","",'PEDIDO WEPP'!H16) -> 6 | I16: =IF(B16="","",'PEDIDO WEPP'!I16) -> 2.95 | J16: =IF(B16="","",'PEDIDO WEPP'!J16) -> 17.7
B17: ='PEDIDO WEPP'!C17 -> 2010 SF | C17: =IF(B17="","",VLOOKUP(B17,DATOS!$F$3:$H$139,3,FALSE)) -> Motor System Reiniger (Lösungsmittelfrei) | D17: =IF(B17="","",'PEDIDO WEPP'!D17) -> 300 ml | E17: =IF(B17="","",'PEDIDO WEPP'!E17) -> unidad | F17: =IF(E17="CAJA","KISTE",IF(E17="unidad","STÜCK","")) -> STÜCK | G17: =IF(B17="","",'PEDIDO WEPP'!F17) -> 2 | H17: =IF(B17="","",'PEDIDO WEPP'!H17) -> 2 | I17: =IF(B17="","",'PEDIDO WEPP'!I17) -> 2.95 | J17: =IF(B17="","",'PEDIDO WEPP'!J17) -> 5.9
B18: ='PEDIDO WEPP'!C18 -> 2010 SF | C18: =IF(B18="","",VLOOKUP(B18,DATOS!$F$3:$H$139,3,FALSE)) -> Motor System Reiniger (Lösungsmittelfrei) | D18: =IF(B18="","",'PEDIDO WEPP'!D18) -> 300 ml | E18: =IF(B18="","",'PEDIDO WEPP'!E18) -> unidad | F18: =IF(E18="CAJA","KISTE",IF(E18="unidad","STÜCK","")) -> STÜCK | G18: =IF(B18="","",'PEDIDO WEPP'!F18) -> 2 | H18: =IF(B18="","",'PEDIDO WEPP'!H18) -> 2 | I18: =IF(B18="","",'PEDIDO WEPP'!I18) -> 2.95 | J18: =IF(B18="","",'PEDIDO WEPP'!J18) -> 5.9
B19: ='PEDIDO WEPP'!C19 -> 2010 SF | C19: =IF(B19="","",VLOOKUP(B19,DATOS!$F$3:$H$139,3,FALSE)) -> Motor System Reiniger (Lösungsmittelfrei) | D19: =IF(B19="","",'PEDIDO WEPP'!D19) -> 300 ml | E19: =IF(B19="","",'PEDIDO WEPP'!E19) -> caja | F19: =IF(E19="CAJA","KISTE",IF(E19="unidad","STÜCK","")) -> KISTE | G19: =IF(B19="","",'PEDIDO WEPP'!F19) -> 2 | H19: =IF(B19="","",'PEDIDO WEPP'!H19) -> 48 | I19: =IF(B19="","",'PEDIDO WEPP'!I19) -> 2.95 | J19: =IF(B19="","",'PEDIDO WEPP'!J19) -> 141.6
B20: ='PEDIDO WEPP'!C20 -> 2010 SF | C20: =IF(B20="","",VLOOKUP(B20,DATOS!$F$3:$H$139,3,FALSE)) -> Motor System Reiniger (Lösungsmittelfrei) | D20: =IF(B20="","",'PEDIDO WEPP'!D20) -> 300 ml | E20: =IF(B20="","",'PEDIDO WEPP'!E20) -> caja | F20: =IF(E20="CAJA","KISTE",IF(E20="unidad","STÜCK","")) -> KISTE | G20: =IF(B20="","",'PEDIDO WEPP'!F20) -> 1 | H20: =IF(B20="","",'PEDIDO WEPP'!H20) -> 24 | I20: =IF(B20="","",'PEDIDO WEPP'!I20) -> 2.95 | J20: =IF(B20="","",'PEDIDO WEPP'!J20) -> 70.8
B21: ='PEDIDO WEPP'!C21 -> 2010 SF | C21: =IF(B21="","",VLOOKUP(B21,DATOS!$F$3:$H$139,3,FALSE)) -> Motor System Reiniger (Lösungsmittelfrei) | D21: =IF(B21="","",'PEDIDO WEPP'!D21) -> 300 ml | E21: =IF(B21="","",'PEDIDO WEPP'!E21) -> unidad | F21: =IF(E21="CAJA","KISTE",IF(E21="unidad","STÜCK","")) -> STÜCK | G21: =IF(B21="","",'PEDIDO WEPP'!F21) -> 12 | H21: =IF(B21="","",'PEDIDO WEPP'!H21) -> 12 | I21: =IF(B21="","",'PEDIDO WEPP'!I21) -> 2.95 | J21: =IF(B21="","",'PEDIDO WEPP'!J21) -> 35.4
... B29: ='PEDIDO WEPP'!C29 -> 2010 SF | C29: =IF(B29="","",VLOOKUP(B29,DATOS!$F$3:$H$139,3,FALSE)) -> Motor System Reiniger (Lösungsmittelfrei) | D29: =IF(B29="","",'PEDIDO WEPP'!D29) -> 300 ml | E29: =IF(B29="","",'PEDIDO WEPP'!E29) -> unidad | F29: =IF(E29="CAJA","KISTE",IF(E29="unidad","STÜCK","")) -> STÜCK | G29: =IF(B29="","",'PEDIDO WEPP'!F29) -> 2 | H29: =IF(B29="","",'PEDIDO WEPP'!H29) -> 2 | I29: =IF(B29="","",'PEDIDO WEPP'!I29) -> 2.95 | J29: =IF(B29="","",'PEDIDO WEPP'!J29) -> 5.9
J30: =SUM(J10:J29) -> 1042.5
B32: PEDIDO | I32: Nº | J32: ='PEDIDO WEPP'!J32 -> 2025-0001
B33: Ref. | C33: PRODUKT | D33: Volumen | E33: Cantidad | G33: STÜCK | H33: Total | I33: Einzelpreis | J33: TOTAL
B34: ='PEDIDO WEPP'!C34 -> 7050250 | C34: =IF(B34="","",VLOOKUP(B34,DATOS!$F$3:$H$139,3,FALSE)) -> AC Leckindikator | D34: =IF(B34="","",'PEDIDO WEPP'!D34) -> 250 ml | E34: =IF(B34="","",'PEDIDO WEPP'!E34) -> unidad | F34: =IF(E34="CAJA","KISTE",IF(E34="unidad","STÜCK","")) -> STÜCK | G34: =IF(B34="","",'PEDIDO WEPP'!F34) -> 2 | H34: =IF(B34="","",'PEDIDO WEPP'!H34) -> 2 | I34: =IF(B34="","",'PEDIDO WEPP'!I34) -> 12.9 | J34: =IF(B34="","",'PEDIDO WEPP'!J34) -> 25.8
B35: ='PEDIDO WEPP'!C35 -> 7035001 | C35: =IF(B35="","",VLOOKUP(B35,DATOS!$F$3:$H$139,3,FALSE)) -> POE 68 + UV | D35: =IF(B35="","",'PEDIDO WEPP'!D35) -> 1000 ml | E35: =IF(B35="","",'PEDIDO WEPP'!E35) -> unidad | F35: =IF(E35="CAJA","KISTE",IF(E35="unidad","STÜCK","")) -> STÜCK | G35: =IF(B35="","",'PEDIDO WEPP'!F35) -> 2 | H35: =IF(B35="","",'PEDIDO WEPP'!H35) -> 2 | I35: =IF(B35="","",'PEDIDO WEPP'!I35) -> 13.85 | J35: =IF(B35="","",'PEDIDO WEPP'!J35) -> 27.7
B36: ='PEDIDO WEPP'!C36 -> 2030 | C36: =IF(B36="","",VLOOKUP(B36,DATOS!$F$3:$H$139,3,FALSE)) -> Diesel Intensiv Reiniger | D36: =IF(B36="","",'PEDIDO WEPP'!D36) -> 500 ml | E36: =IF(B36="","",'PEDIDO WEPP'!E36) -> caja | F36: =IF(E36="CAJA","KISTE",IF(E36="unidad","STÜCK","")) -> KISTE | G36: =IF(B36="","",'PEDIDO WEPP'!F36) -> 2 | H36: =IF(B36="","",'PEDIDO WEPP'!H36) -> 48 | I36: =IF(B36="","",'PEDIDO WEPP'!I36) -> 3.65 | J36: =IF(B36="","",'PEDIDO WEPP'!J36) -> 175.2
B37: ='PEDIDO WEPP'!C37 -> 2130 | C37: =IF(B37="","",VLOOKUP(B37,DATOS!$F$3:$H$139,3,FALSE)) -> Diesel Einlass Reiniger Spray | D37: =IF(B37="","",'PEDIDO WEPP'!D37) -> 400 ml | E37: =IF(B37="","",'PEDIDO WEPP'!E37) -> unidad | F37: =IF(E37="CAJA","KISTE",IF(E37="unidad","STÜCK","")) -> STÜCK | G37: =IF(B37="","",'PEDIDO WEPP'!F37) -> 2 | H37: =IF(B37="","",'PEDIDO WEPP'!H37) -> 2 | I37: =IF(B37="","",'PEDIDO WEPP'!I37) -> 3.95 | J37: =IF(B37="","",'PEDIDO WEPP'!J37) -> 7.9
B38: ='PEDIDO WEPP'!C38 -> 2230 | C38: =IF(B38="","",VLOOKUP(B38,DATOS!$F$3:$H$139,3,FALSE)) -> Turbo AGR Ansaugreiniger | D38: =IF(B38="","",'PEDIDO WEPP'!D38) -> 400 ml | E38: =IF(B38="","",'PEDIDO WEPP'!E38) -> unidad | F38: =IF(E38="CAJA","KISTE",IF(E38="unidad","STÜCK","")) -> STÜCK | G38: =IF(B38="","",'PEDIDO WEPP'!F38) -> 4 | H38: =IF(B38="","",'PEDIDO WEPP'!H38) -> 4 | I38: =IF(B38="","",'PEDIDO WEPP'!I38) -> 6.5 | J38: =IF(B38="","",'PEDIDO WEPP'!J38) -> 26
B39: ='PEDIDO WEPP'!C39 -> 2031 | C39: =IF(B39="","",VLOOKUP(B39,DATOS!$F$3:$H$139,3,FALSE)) -> Drosselklappen + Vergaserreiniger | D39: =IF(B39="","",'PEDIDO WEPP'!D39) -> 400 ml | E39: =IF(B39="","",'PEDIDO WEPP'!E39) -> unidad | F39: =IF(E39="CAJA","KISTE",IF(E39="unidad","STÜCK","")) -> STÜCK | G39: =IF(B39="","",'PEDIDO WEPP'!F39) -> 4 | H39: =IF(B39="","",'PEDIDO WEPP'!H39) -> 4 | I39: =IF(B39="","",'PEDIDO WEPP'!I39) -> 3.5 | J39: =IF(B39="","",'PEDIDO WEPP'!J39) -> 14
B40: ='PEDIDO WEPP'!C40 -> 2032-300 | C40: =IF(B40="","",VLOOKUP(B40,DATOS!$F$3:$H$139,3,FALSE)) -> Diesel System Schutz | D40: =IF(B40="","",'PEDIDO WEPP'!D40) -> 300 ml | E40: =IF(B40="","",'PEDIDO WEPP'!E40) -> caja | F40: =IF(E40="CAJA","KISTE",IF(E40="unidad","STÜCK","")) -> KISTE | G40: =IF(B40="","",'PEDIDO WEPP'!F40) -> 2 | H40: =IF(B40="","",'PEDIDO WEPP'!H40) -> 48 | I40: =IF(B40="","",'PEDIDO WEPP'!I40) -> 2.55 | J40: =IF(B40="","",'PEDIDO WEPP'!J40) -> 122.4
B41: ='PEDIDO WEPP'!C41 -> 2032+ | C41: =IF(B41="","",VLOOKUP(B41,DATOS!$F$3:$H$139,3,FALSE)) -> Diesel Complete Clean | D41: =IF(B41="","",'PEDIDO WEPP'!D41) -> 250 ml | E41: =IF(B41="","",'PEDIDO WEPP'!E41) -> caja | F41: =IF(E41="CAJA","KISTE",IF(E41="unidad","STÜCK","")) -> KISTE | G41: =IF(B41="","",'PEDIDO WEPP'!F41) -> 2 | H41: =IF(B41="","",'PEDIDO WEPP'!H41) -> 48 | I41: =IF(B41="","",'PEDIDO WEPP'!I41) -> 3.6 | J41: =IF(B41="","",'PEDIDO WEPP'!J41) -> 172.8
B42: ='PEDIDO WEPP'!C42 -> 732 | C42: =IF(B42="","",VLOOKUP(B42,DATOS!$F$3:$H$139,3,FALSE)) -> SCR Schutz | D42: =IF(B42="","",'PEDIDO WEPP'!D42) -> 50 ml | E42: =IF(B42="","",'PEDIDO WEPP'!E42) -> unidad | F42: =IF(E42="CAJA","KISTE",IF(E42="unidad","STÜCK","")) -> STÜCK | G42: =IF(B42="","",'PEDIDO WEPP'!F42) -> 20 | H42: =IF(B42="","",'PEDIDO WEPP'!H42) -> 20 | I42: =IF(B42="","",'PEDIDO WEPP'!I42) -> 1.2 | J42: =IF(B42="","",'PEDIDO WEPP'!J42) -> 24
B43: ='PEDIDO WEPP'!C43 -> 2132-300 | C43: =IF(B43="","",VLOOKUP(B43,DATOS!$F$3:$H$139,3,FALSE)) -> DPF/ Turbo Cleaner | D43: =IF(B43="","",'PEDIDO WEPP'!D43) -> 300 ml | E43: =IF(B43="","",'PEDIDO WEPP'!E43) -> caja | F43: =IF(E43="CAJA","KISTE",IF(E43="unidad","STÜCK","")) -> KISTE | G43: =IF(B43="","",'PEDIDO WEPP'!F43) -> 4 | H43: =IF(B43="","",'PEDIDO WEPP'!H43) -> 96 | I43: =IF(B43="","",'PEDIDO WEPP'!I43) -> 3.9 | J43: =IF(B43="","",'PEDIDO WEPP'!J43) -> 374.4
B44: ='PEDIDO WEPP'!C44 -> 2232 | C44: =IF(B44="","",VLOOKUP(B44,DATOS!$F$3:$H$139,3,FALSE)) -> DPF Direct Cleaner | D44: =IF(B44="","",'PEDIDO WEPP'!D44) -> 500 ml | E44: =IF(B44="","",'PEDIDO WEPP'!E44) -> unidad | F44: =IF(E44="CAJA","KISTE",IF(E44="unidad","STÜCK","")) -> STÜCK | G44: =IF(B44="","",'PEDIDO WEPP'!F44) -> 1 | H44: =IF(B44="","",'PEDIDO WEPP'!H44) -> 1 | I44: =IF(B44="","",'PEDIDO WEPP'!I44) -> 6.85 | J44: =IF(B44="","",'PEDIDO WEPP'!J44) -> 6.85
B45: ='PEDIDO WEPP'!C45 -> 39001 | C45: =IF(B45="","",VLOOKUP(B45,DATOS!$F$3:$H$139,3,FALSE)) -> Hohlraumschlauch | D45: =IF(B45="","",'PEDIDO WEPP'!D45) -> - ml | E45: =IF(B45="","",'PEDIDO WEPP'!E45) -> unidad | F45: =IF(E45="CAJA","KISTE",IF(E45="unidad","STÜCK","")) -> STÜCK | G45: =IF(B45="","",'PEDIDO WEPP'!F45) -> 1 | H45: =IF(B45="","",'PEDIDO WEPP'!H45) -> 1 | I45: =IF(B45="","",'PEDIDO WEPP'!I45) -> 20 | J45: =IF(B45="","",'PEDIDO WEPP'!J45) -> 20
... B61: ='PEDIDO WEPP'!C61 -> 2043 | C61: =IF(B61="","",VLOOKUP(B61,DATOS!$F$3:$H$139,3,FALSE)) -> Wartungs Haftöl | D61: =IF(B61="","",'PEDIDO WEPP'!D61) -> 400 ml | E61: =IF(B61="","",'PEDIDO WEPP'!E61) -> unidad | F61: =IF(E61="CAJA","KISTE",IF(E61="unidad","STÜCK","")) -> STÜCK | G61: =IF(B61="","",'PEDIDO WEPP'!F61) -> 4 | H61: =IF(B61="","",'PEDIDO WEPP'!H61) -> 4 | I61: =IF(B61="","",'PEDIDO WEPP'!I61) -> 3.15 | J61: =IF(B61="","",'PEDIDO WEPP'!J61) -> 12.6
J62: =SUM(J34:J61) -> 1718.05
B63: PEDIDO | I63: Nº | J63: ='PEDIDO WEPP'!J63 -> 2025-0001
...

Sheet CLIENTE PEDIDO
B1: DATOS CLIENTE
B2: Razón Social:
B3: CIF:
B4: Dirección:
B5: Dirección envío:
B6: Teléfono:
B7: Correo Electrónico:
B8: FACTURA PROFORMA | I8: Nº | M8: 2025-1
B9: Descripción | C9: Ref. | D9: Volumen | E9: Cantidad | F9: Unidad | G9: ocultar | H9: Total | I9: Precio ud | J9: ocultar | K9: ocultar | L9: ocultar | M9: Dto(%) | N9: ocultar | O9: Total B.I. | V9: unidad
A10: motor | B10: Limpiador de Motor SF (sin disolventes) | C10: =IF(B10="-","",VLOOKUP(B10,DATOS!$I$3:$K$200,2,FALSE)) -> 2010 SF | D10: =IF(B10="-","",CONCATENATE(VLOOKUP(C10,DATOS!$J$3:$K$200,2,FALSE)," ml")) -> 300 ml | E10: unidad | F10: 12 | G10: =IF(B10="-","",IF(E10="caja",VLOOKUP(B10,DATOS!$I$3:$AC$137,21,FALSE),F10)) -> 12 | H10: =IF(B10="-","",IF(E10="caja",F10*G10,F10)) -> 12 | I10: =IF(B10="-","",VLOOKUP(B10,DATOS!$I$3:$S$138,11,FALSE)) -> 10.285 | J10: =IF(B10="-","",H10*I10) -> 123.42 | K10: =VLOOKUP(B10,DATOS!$I$3:$AD$138,19,FALSE) -> 8 | L10: =IF(E10="caja",VLOOKUP(B10,DATOS!$I$3:$AD$138,22,FALSE),VLOOKUP(B10,DATOS!$I$3:$AD$138,20,FALSE)) -> 5 | M10: =IF(B10="-","",IF(E10="caja",L10,IF(F10>K10,L10,"0"))) -> 5 | N10: =IF(B10="-","",(100-M10)/100) -> 0.95 | O10: =IF(B10="-","",J10*N10) -> 117.249 | Q10: =I10*0.21*N10 -> 2.0518575 | R10: =I10*N10+Q10 -> 11.822608 | S10: =R10*H10 -> 141.87129 | V10: caja
A11: refrigeracion | B11: Protector del Sistema de Refrigeración | C11: =IF(B11="-","",VLOOKUP(B11,DATOS!$I$3:$K$200,2,FALSE)) -> 2020 | D11: =IF(B11="-","",CONCATENATE(VLOOKUP(C11,DATOS!$J$3:$K$200,2,FALSE)," ml")) -> 300 ml | E11: caja | F11: 1 | G11: =IF(B11="-","",IF(E11="caja",VLOOKUP(B11,DATOS!$I$3:$AC$137,21,FALSE),F11)) -> 24 | H11: =IF(B11="-","",IF(E11="caja",F11*G11,F11)) -> 24 | I11: =IF(B11="-","",VLOOKUP(B11,DATOS!$I$3:$S$138,11,FALSE)) -> 8.47 | J11: =IF(B11="-","",H11*I11) -> 203.28 | K11: =VLOOKUP(B11,DATOS!$I$3:$AD$138,19,FALSE) -> 8 | L11: =IF(E11="caja",VLOOKUP(B11,DATOS!$I$3:$AD$138,22,FALSE),VLOOKUP(B11,DATOS!$I$3:$AD$138,20,FALSE)) -> 15 | M11: =IF(B11="-","",IF(E11="caja",L11,IF(F11>K11,L11,"0"))) -> 15 | N11: =IF(B11="-","",(100-M11)/100) -> 0.85 | O11: =IF(B11="-","",J11*N11) -> 172.788 | Q11: =I11*0.21*N11 -> 1.511895 | R11: =I11*N11+Q11 -> 8.711395 | S11: =R11*H11 -> 209.07348
A12: climatizacion | B12: Airfresh Menta | C12: =IF(B12="-","",VLOOKUP(B12,DATOS!$I$3:$K$200,2,FALSE)) -> 2125 | D12: =IF(B12="-","",CONCATENATE(VLOOKUP(C12,DATOS!$J$3:$K$200,2,FALSE)," ml")) -> 100 ml | E12: caja | F12: 1 | G12: =IF(B12="-","",IF(E12="caja",VLOOKUP(B12,DATOS!$I$3:$AC$137,21,FALSE),F12)) -> 24 | H12: =IF(B12="-","",IF(E12="caja",F12*G12,F12)) -> 24 | I12: =IF(B12="-","",VLOOKUP(B12,DATOS!$I$3:$S$138,11,FALSE)) -> 10.175 | J12: =IF(B12="-","",H12*I12) -> 244.2 | K12: =VLOOKUP(B12,DATOS!$I$3:$AD$138,19,FALSE) -> 8 | L12: =IF(E12="caja",VLOOKUP(B12,DATOS!$I$3:$AD$138,22,FALSE),VLOOKUP(B12,DATOS!$I$3:$AD$138,20,FALSE)) -> 15 | M12: =IF(B12="-","",IF(E12="caja",L12,IF(F12>K12,L12,"0"))) -> 15 | N12: =IF(B12="-","",(100-M12)/100) -> 0.85 | O12: =IF(B12="-","",J12*N12) -> 207.57 | Q12: =I12*0.21*N12 -> 1.8162375 | R12: =I12*N12+Q12 -> 10.464987 | S12: =R12*H12 -> 251.1597
A13: combustion | B13: Limpiador Intensivo Diésel | C13: =IF(B13="-","",VLOOKUP(B13,DATOS!$I$3:$K$200,2,FALSE)) -> 2030 | D13: =IF(B13="-","",CONCATENATE(VLOOKUP(C13,DATOS!$J$3:$K$200,2,FALSE)," ml")) -> 500 ml | E13: unidad | F13: 3 | G13: =IF(B13="-","",IF(E13="caja",VLOOKUP(B13,DATOS!$I$3:$AC$137,21,FALSE),F13)) -> 3 | H13: =IF(B13="-","",IF(E13="caja",F13*G13,F13)) -> 3 | I13: =IF(B13="-","",VLOOKUP(B13,DATOS!$I$3:$S$138,11,FALSE)) -> 9.955 | J13: =IF(B13="-","",H13*I13) -> 29.865 | K13: =VLOOKUP(B13,DATOS!$I$3:$AD$138,19,FALSE) -> 8 | L13: =IF(E13="caja",VLOOKUP(B13,DATOS!$I$3:$AD$138,22,FALSE),VLOOKUP(B13,DATOS!$I$3:$AD$138,20,FALSE)) -> 5 | M13: =IF(B13="-","",IF(E13="caja",L13,IF(F13>K13,L13,"0"))) -> 0 | N13: =IF(B13="-","",(100-M13)/100) -> 1 | O13: =IF(B13="-","",J13*N13) -> 29.865 | Q13: =I13*0.21*N13 -> 2.09055 | R13: =I13*N13+Q13 -> 12.04555 | S13: =R13*H13 -> 36.13665
A14: frenos | B14: Frenos Hi Tec | C14: =IF(B14="-","",VLOOKUP(B14,DATOS!$I$3:$K$200,2,FALSE)) -> 255 | D14: =IF(B14="-","",CONCATENATE(VLOOKUP(C14,DATOS!$J$3:$K$200,2,FALSE)," ml")) -> 400 ml | E14: unidad | F14: 5 | G14: =IF(B14="-","",IF(E14="caja",VLOOKUP(B14,DATOS!$I$3:$AC$137,21,FALSE),F14)) -> 5 | H14: =IF(B14="-","",IF(E14="caja",F14*G14,F14)) -> 5 | I14: =IF(B14="-","",VLOOKUP(B14,DATOS!$I$3:$S$138,11,FALSE)) -> 11.66 | J14: =IF(B14="-","",H14*I14) -> 58.3 | K14: =VLOOKUP(B14,DATOS!$I$3:$AD$138,19,FALSE) -> 8 | L14: =IF(E14="caja",VLOOKUP(B14,DATOS!$I$3:$AD$138,22,FALSE),VLOOKUP(B14,DATOS!$I$3:$AD$138,20,FALSE)) -> 5 | M14: =IF(B14="-","",IF(E14="caja",L14,IF(F14>K14,L14,"0"))) -> 0 | N14: =IF(B14="-","",(100-M14)/100) -> 1 | O14: =IF(B14="-","",J14*N14) -> 58.3 | Q14: =I14*0.21*N14 -> 2.4486 | R14: =I14*N14+Q14 -> 14.1086 | S14: =R14*H14 -> 70.543
A15: mantenimiento | B15: - | C15: =IF(B15="-","",VLOOKUP(B15,DATOS!$I$3:$K$200,2,FALSE)) | D15: =IF(B15="-","",CONCATENATE(VLOOKUP(C15,DATOS!$J$3:$K$200,2,FALSE)," ml")) | G15: =IF(B15="-","",IF(E15="caja",VLOOKUP(B15,DATOS!$I$3:$AC$137,21,FALSE),F15)) | H15: =IF(B15="-","",IF(E15="caja",F15*G15,F15)) | I15: =IF(B15="-","",VLOOKUP(B15,DATOS!$I$3:$S$138,11,FALSE)) | J15: =IF(B15="-","",H15*I15) | K15: =VLOOKUP(B15,DATOS!$I$3:$AD$138,19,FALSE) -> 0 | L15: =IF(E15="caja",VLOOKUP(B15,DATOS!$I$3:$AD$138,22,FALSE),VLOOKUP(B15,DATOS!$I$3:$AD$138,20,FALSE)) -> 5 | M15: =IF(B15="-","",IF(E15="caja",L15,IF(F15>K15,L15,"0"))) | N15: =IF(B15="-","",(100-M15)/100) | O15: =IF(B15="-","",J15*N15)
A16: carroceria | B16: - | C16: =IF(B16="-","",VLOOKUP(B16,DATOS!$I$3:$K$200,2,FALSE)) | D16: =IF(B16="-","",CONCATENATE(VLOOKUP(C16,DATOS!$J$3:$K$200,2,FALSE)," ml")) | G16: =IF(B16="-","",IF(E16="caja",VLOOKUP(B16,DATOS!$I$3:$AC$137,21,FALSE),F16)) | H16: =IF(B16="-","",IF(E16="caja",F16*G16,F16)) | I16: =IF(B16="-","",VLOOKUP(B16,DATOS!$I$3:$S$138,11,FALSE)) | J16: =IF(B16="-","",H16*I16) | K16: =VLOOKUP(B16,DATOS!$I$3:$AD$138,19,FALSE) -> 0 | L16: =IF(E16="caja",VLOOKUP(B16,DATOS!$I$3:$AD$138,22,FALSE),VLOOKUP(B16,DATOS!$I$3:$AD$138,20,FALSE)) -> 5 | M16: =IF(B16="-","",IF(E16="caja",L16,IF(F16>K16,L16,"0"))) | N16: =IF(B16="-","",(100-M16)/100) | O16: =IF(B16="-","",J16*N16)
A17: refrigeracion | B17: - | C17: =IF(B17="-","",VLOOKUP(B17,DATOS!$I$3:$K$200,2,FALSE)) | D17: =IF(B17="-","",CONCATENATE(VLOOKUP(C17,DATOS!$J$3:$K$200,2,FALSE)," ml")) | G17: =IF(B17="-","",IF(E17="caja",VLOOKUP(B17,DATOS!$I$3:$AC$137,21,FALSE),F17)) | H17: =IF(B17="-","",IF(E17="caja",F17*G17,F17)) | I17: =IF(B17="-","",VLOOKUP(B17,DATOS!$I$3:$S$138,11,FALSE)) | J17: =IF(B17="-","",H17*I17) | K17: =VLOOKUP(B17,DATOS!$I$3:$AD$138,19,FALSE) -> 0 | L17: =IF(E17="caja",VLOOKUP(B17,DATOS!$I$3:$AD$138,22,FALSE),VLOOKUP(B17,DATOS!$I$3:$AD$138,20,FALSE)) -> 5 | M17: =IF(B17="-","",IF(E17="caja",L17,IF(F17>K17,L17,"0"))) | N17: =IF(B17="-","",(100-M17)/100) | O17: =IF(B17="-","",J17*N17)
A18: climatizacion | B18: - | C18: =IF(B18="-","",VLOOKUP(B18,DATOS!$I$3:$K$200,2,FALSE)) | D18: =IF(B18="-","",CONCATENATE(VLOOKUP(C18,DATOS!$J$3:$K$200,2,FALSE)," ml")) | G18: =IF(B18="-","",IF(E18="caja",VLOOKUP(B18,DATOS!$I$3:$AC$137,21,FALSE),F18)) | H18: =IF(B18="-","",IF(E18="caja",F18*G18,F18)) | I18: =IF(B18="-","",VLOOKUP(B18,DATOS!$I$3:$S$138,11,FALSE)) | J18: =IF(B18="-","",H18*I18) | K18: =VLOOKUP(B18,DATOS!$I$3:$AD$138,19,FALSE) -> 0 | L18: =IF(E18="caja",VLOOKUP(B18,DATOS!$I$3:$AD$138,22,FALSE),VLOOKUP(B18,DATOS!$I$3:$AD$138,20,FALSE)) -> 5 | M18: =IF(B18="-","",IF(E18="caja",L18,IF(F18>K18,L18,"0"))) | N18: =IF(B18="-","",(100-M18)/100) | O18: =IF(B18="-","",J18*N18)
A19: motor | B19: - | C19: =IF(B19="-","",VLOOKUP(B19,DATOS!$I$3:$K$200,2,FALSE)) | D19: =IF(B19="-","",CONCATENATE(VLOOKUP(C19,DATOS!$J$3:$K$200,2,FALSE)," ml")) | G19: =IF(B19="-","",IF(E19="caja",VLOOKUP(B19,DATOS!$I$3:$AC$137,21,FALSE),F19)) | H19: =IF(B19="-","",IF(E19="caja",F19*G19,F19)) | I19: =IF(B19="-","",VLOOKUP(B19,DATOS!$I$3:$S$138,11,FALSE)) | J19: =IF(B19="-","",H19*I19) | K19: =VLOOKUP(B19,DATOS!$I$3:$AD$138,19,FALSE) -> 0 | L19: =IF(E19="caja",VLOOKUP(B19,DATOS!$I$3:$AD$138,22,FALSE),VLOOKUP(B19,DATOS!$I$3:$AD$138,20,FALSE)) -> 5 | M19: =IF(B19="-","",IF(E19="caja",L19,IF(F19>K19,L19,"0"))) | N19: =IF(B19="-","",(100-M19)/100) | O19: =IF(B19="-","",J19*N19)
A20: refrigeracion | B20: - | C20: =IF(B20="-","",VLOOKUP(B20,DATOS!$I$3:$K$200,2,FALSE)) | D20: =IF(B20="-","",CONCATENATE(VLOOKUP(C20,DATOS!$J$3:$K$200,2,FALSE)," ml")) | G20: =IF(B20="-","",IF(E20="caja",VLOOKUP(B20,DATOS!$I$3:$AC$137,21,FALSE),F20)) | H20: =IF(B20="-","",IF(E20="caja",F20*G20,F20)) | I20: =IF(B20="-","",VLOOKUP(B20,DATOS!$I$3:$S$138,11,FALSE)) | J20: =IF(B20="-","",H20*I20) | K20: =VLOOKUP(B20,DATOS!$I$3:$AD$138,19,FALSE) -> 0 | L20: =IF(E20="caja",VLOOKUP(B20,DATOS!$I$3:$AD$138,22,FALSE),VLOOKUP(B20,DATOS!$I$3:$AD$138,20,FALSE)) -> 5 | M20: =IF(B20="-","",IF(E20="caja",L20,IF(F20>K20,L20,"0"))) | N20: =IF(B20="-","",(100-M20)/100) | O20: =IF(B20="-","",J20*N20)
A21: climatizacion | B21: - | C21: =IF(B21="-","",VLOOKUP(B21,DATOS!$I$3:$K$200,2,FALSE)) | D21: =IF(B21="-","",CONCATENATE(VLOOKUP(C21,DATOS!$J$3:$K$200,2,FALSE)," ml")) | G21: =IF(B21="-","",IF(E21="caja",VLOOKUP(B21,DATOS!$I$3:$AC$137,21,FALSE),F21)) | H21: =IF(B21="-","",IF(E21="caja",F21*G21,F21)) | I21: =IF(B21="-","",VLOOKUP(B21,DATOS!$I$3:$S$138,11,FALSE)) | J21: =IF(B21="-","",H21*I21) | K21: =VLOOKUP(B21,DATOS!$I$3:$AD$138,19,FALSE) -> 0 | L21: =IF(E21="caja",VLOOKUP(B21,DATOS!$I$3:$AD$138,22,FALSE),VLOOKUP(B21,DATOS!$I$3:$AD$138,20,FALSE)) -> 5 | M21: =IF(B21="-","",IF(E21="caja",L21,IF(F21>K21,L21,"0"))) | N21: =IF(B21="-","",(100-M21)/100) | O21: =IF(B21="-","",J21*N21)
A22: motor | B22: - | C22: =IF(B22="-","",VLOOKUP(B22,DATOS!$I$3:$K$200,2,FALSE)) | D22: =IF(B22="-","",CONCATENATE(VLOOKUP(C22,DATOS!$J$3:$K$200,2,FALSE)," ml")) | G22: =IF(B22="-","",IF(E22="caja",VLOOKUP(B22,DATOS!$I$3:$AC$137,21,FALSE),F22)) | H22: =IF(B22="-","",IF(E22="caja",F22*G22,F22)) | I22: =IF(B22="-","",VLOOKUP(B22,DATOS!$I$3:$S$138,11,FALSE)) | J22: =IF(B22="-","",H22*I22) | K22: =VLOOKUP(B22,DATOS!$I$3:$AD$138,19,FALSE) -> 0 | L22: =IF(E22="caja",VLOOKUP(B22,DATOS!$I$3:$AD$138,22,FALSE),VLOOKUP(B22,DATOS!$I$3:$AD$138,20,FALSE)) -> 5 | M22: =IF(B22="-","",IF(E22="caja",L22,IF(F22>K22,L22,"0"))) | N22: =IF(B22="-","",(100-M22)/100) | O22: =IF(B22="-","",J22*N22)
A23: refrigeracion | B23: - | C23: =IF(B23="-","",VLOOKUP(B23,DATOS!$I$3:$K$200,2,FALSE)) | D23: =IF(B23="-","",CONCATENATE(VLOOKUP(C23,DATOS!$J$3:$K$200,2,FALSE)," ml")) | G23: =IF(B23="-","",IF(E23="caja",VLOOKUP(B23,DATOS!$I$3:$AC$137,21,FALSE),F23)) | H23: =IF(B23="-","",IF(E23="caja",F23*G23,F23)) | I23: =IF(B23="-","",VLOOKUP(B23,DATOS!$I$3:$S$138,11,FALSE)) | J23: =IF(B23="-","",H23*I23) | K23: =VLOOKUP(B23,DATOS!$I$3:$AD$138,19,FALSE) -> 0 | L23: =IF(E23="caja",VLOOKUP(B23,DATOS!$I$3:$AD$138,22,FALSE),VLOOKUP(B23,DATOS!$I$3:$AD$138,20,FALSE)) -> 5 | M23: =IF(B23="-","",IF(E23="caja",L23,IF(F23>K23,L23,"0"))) | N23: =IF(B23="-","",(100-M23)/100) | O23: =IF(B23="-","",J23*N23)
A24: climatizacion | B24: - | C24: =IF(B24="-","",VLOOKUP(B24,DATOS!$I$3:$K$200,2,FALSE)) | D24: =IF(B24="-","",CONCATENATE(VLOOKUP(C24,DATOS!$J$3:$K$200,2,FALSE)," ml")) | G24: =IF(B24="-","",IF(E24="caja",VLOOKUP(B24,DATOS!$I$3:$AC$137,21,FALSE),F24)) | H24: =IF(B24="-","",IF(E24="caja",F24*G24,F24)) | I24: =IF(B24="-","",VLOOKUP(B24,DATOS!$I$3:$S$138,11,FALSE)) | J24: =IF(B24="-","",H24*I24) | K24: =VLOOKUP(B24,DATOS!$I$3:$AD$138,19,FALSE) -> 0 | L24: =IF(E24="caja",VLOOKUP(B24,DATOS!$I$3:$AD$138,22,FALSE),VLOOKUP(B24,DATOS!$I$3:$AD$138,20,FALSE)) -> 5 | M24: =IF(B24="-","",IF(E24="caja",L24,IF(F24>K24,L24,"0"))) | N24: =IF(B24="-","",(100-M24)/100) | O24: =IF(B24="-","",J24*N24)
M25: TOTAL B.I. | O25: =SUM(O10:O24) -> 585.772 | Q25: =SUM(Q10:Q24) -> 9.91914 | R25: =SUM(R10:R24) -> 57.15314 | S25: =SUM(S10:S24) -> 708.78412
M26: I.V.A. (21%) | N26: 0.21 | O26: =O25*0.21 -> 123.01212
O27: =O25+O26 -> 708.78412
B29: Michael Leffler | C29: Peones Camineros, Portal A 2 izq. 11158. La barca de Vejer
B30: X-0000000000-W | D30: 600 100 100 | F30: pedidos@wepp.es
B31: CCC | C31: 2100 1789 0100 0000 0001

Sheet CLIENTE FACTURA
A1: DATOS CLIENTE
A2: Razón Social:
A3: CIF:
A4: Dirección:
A5: Dirección envío:
A6: Teléfono:
A7: Correo Electrónico:
A8: FACTURA | G8: Nº | H8: 2025-1
A9: Descripción | B9: Ref. | C9: Volumen | D9: Cantidad | E9: Unidad | F9: Total | G9: Precio ud | H9: Dto(%) | I9: Total B.I.
A10: ='CLIENTE PEDIDO'!B10 -> Limpiador de Motor SF (sin disolventes) | B10: ='CLIENTE PEDIDO'!C10 -> 2010 SF | C10: ='CLIENTE PEDIDO'!D10 -> 300 ml | D10: =IF(A10="-","",'CLIENTE PEDIDO'!E10) -> unidad | E10: =IF(A10="-","",'CLIENTE PEDIDO'!F10) -> 12 | F10: ='CLIENTE PEDIDO'!H10 -> 12 | G10: ='CLIENTE PEDIDO'!I10 -> 10.285 | H10: ='CLIENTE PEDIDO'!M10 -> 5 | I10: ='CLIENTE PEDIDO'!O10 -> 117.249
A11: ='CLIENTE PEDIDO'!B11 -> Protector del Sistema de Refrigeración | B11: ='CLIENTE PEDIDO'!C11 -> 2020 | C11: ='CLIENTE PEDIDO'!D11 -> 300 ml | D11: =IF(A11="-","",'CLIENTE PEDIDO'!E11) -> caja | E11: =IF(A11="-","",'CLIENTE PEDIDO'!F11) -> 1 | F11: ='CLIENTE PEDIDO'!H11 -> 24 | G11: ='CLIENTE PEDIDO'!I11 -> 8.47 | H11: ='CLIENTE PEDIDO'!M11 -> 15 | I11: ='CLIENTE PEDIDO'!O11 -> 172.788
A12: ='CLIENTE PEDIDO'!B12 -> Airfresh Menta | B12: ='CLIENTE PEDIDO'!C12 -> 2125 | C12: ='CLIENTE PEDIDO'!D12 -> 100 ml | D12: =IF(A12="-","",'CLIENTE PEDIDO'!E12) -> caja | E12: =IF(A12="-","",'CLIENTE PEDIDO'!F12) -> 1 | F12: ='CLIENTE PEDIDO'!H12 -> 24 | G12: ='CLIENTE PEDIDO'!I12 -> 10.175 | H12: ='CLIENTE PEDIDO'!M12 -> 15 | I12: ='CLIENTE PEDIDO'!O12 -> 207.57
A13: ='CLIENTE PEDIDO'!B13 -> Limpiador Intensivo Diésel | B13: ='CLIENTE PEDIDO'!C13 -> 2030 | C13: ='CLIENTE PEDIDO'!D13 -> 500 ml | D13: =IF(A13="-","",'CLIENTE PEDIDO'!E13) -> unidad | E13: =IF(A13="-","",'CLIENTE PEDIDO'!F13) -> 3 | F13: ='CLIENTE PEDIDO'!H13 -> 3 | G13: ='CLIENTE PEDIDO'!I13 -> 9.955 | H13: ='CLIENTE PEDIDO'!M13 -> 0 | I13: ='CLIENTE PEDIDO'!O13 -> 29.865
A14: ='CLIENTE PEDIDO'!B14 -> Frenos Hi Tec | B14: ='CLIENTE PEDIDO'!C14 -> 255 | C14: ='CLIENTE PEDIDO'!D14 -> 400 ml | D14: =IF(A14="-","",'CLIENTE PEDIDO'!E14) -> unidad | E14: =IF(A14="-","",'CLIENTE PEDIDO'!F14) -> 5 | F14: ='CLIENTE PEDIDO'!H14 -> 5 | G14: ='CLIENTE PEDIDO'!I14 -> 11.66 | H14: ='CLIENTE PEDIDO'!M14 -> 0 | I14: ='CLIENTE PEDIDO'!O14 -> 58.3
A15: ='CLIENTE PEDIDO'!B15 -> - | B15: ='CLIENTE PEDIDO'!C15 | C15: ='CLIENTE PEDIDO'!D15 | D15: =IF(A15="-","",'CLIENTE PEDIDO'!E15) | E15: =IF(A15="-","",'CLIENTE PEDIDO'!F15) | F15: ='CLIENTE PEDIDO'!H15 | G15: ='CLIENTE PEDIDO'!I15 | H15: ='CLIENTE PEDIDO'!M15 | I15: ='CLIENTE PEDIDO'!O15
A16: ='CLIENTE PEDIDO'!B16 -> - | B16: ='CLIENTE PEDIDO'!C16 | C16: ='CLIENTE PEDIDO'!D16 | D16: =IF(A16="-","",'CLIENTE PEDIDO'!E16) | E16: =IF(A16="-","",'CLIENTE PEDIDO'!F16) | F16: ='CLIENTE PEDIDO'!H16 | G16: ='CLIENTE PEDIDO'!I16 | H16: ='CLIENTE PEDIDO'!M16 | I16: ='CLIENTE PEDIDO'!O16
A17: ='CLIENTE PEDIDO'!B17 -> - | B17: ='CLIENTE PEDIDO'!C17 | C17: ='CLIENTE PEDIDO'!D17 | D17: =IF(A17="-","",'CLIENTE PEDIDO'!E17) | E17: =IF(A17="-","",'CLIENTE PEDIDO'!F17) | F17: ='CLIENTE PEDIDO'!H17 | G17: ='CLIENTE PEDIDO'!I17 | H17: ='CLIENTE PEDIDO'!M17 | I17: ='CLIENTE PEDIDO'!O17
A18: ='CLIENTE PEDIDO'!B18 -> - | B18: ='CLIENTE PEDIDO'!C18 | C18: ='CLIENTE PEDIDO'!D18 | D18: =IF(A18="-","",'CLIENTE PEDIDO'!E18) | E18: =IF(A18="-","",'CLIENTE PEDIDO'!F18) | F18: ='CLIENTE PEDIDO'!H18 | G18: ='CLIENTE PEDIDO'!I18 | H18: ='CLIENTE PEDIDO'!M18 | I18: ='CLIENTE PEDIDO'!O18
A19: ='CLIENTE PEDIDO'!B19 -> - | B19: ='CLIENTE PEDIDO'!C19 | C19: ='CLIENTE PEDIDO'!D19 | D19: =IF(A19="-","",'CLIENTE PEDIDO'!E19) | E19: =IF(A19="-","",'CLIENTE PEDIDO'!F19) | F19: ='CLIENTE PEDIDO'!H19 | G19: ='CLIENTE PEDIDO'!I19 | H19: ='CLIENTE PEDIDO'!M19 | I19: ='CLIENTE PEDIDO'!O19
A20: ='CLIENTE PEDIDO'!B20 -> - | B20: ='CLIENTE PEDIDO'!C20 | C20: ='CLIENTE PEDIDO'!D20 | D20: =IF(A20="-","",'CLIENTE PEDIDO'!E20) | E20: =IF(A20="-","",'CLIENTE PEDIDO'!F20) | F20: ='CLIENTE PEDIDO'!H20 | G20: ='CLIENTE PEDIDO'!I20 | H20: ='CLIENTE PEDIDO'!M20 | I20: ='CLIENTE PEDIDO'!O20
A21: ='CLIENTE PEDIDO'!B21 -> - | B21: ='CLIENTE PEDIDO'!C21 | C21: ='CLIENTE PEDIDO'!D21 | D21: =IF(A21="-","",'CLIENTE PEDIDO'!E21) | E21: =IF(A21="-","",'CLIENTE PEDIDO'!F21) | F21: ='CLIENTE PEDIDO'!H21 | G21: ='CLIENTE PEDIDO'!I21 | H21: ='CLIENTE PEDIDO'!M21 | I21: ='CLIENTE PEDIDO'!O21
... A24: ='CLIENTE PEDIDO'!B24 -> - | B24: ='CLIENTE PEDIDO'!C24 | C24: ='CLIENTE PEDIDO'!D24 | D24: =IF(A24="-","",'CLIENTE PEDIDO'!E24) | E24: =IF(A24="-","",'CLIENTE PEDIDO'!F24) | F24: ='CLIENTE PEDIDO'!H24 | G24: ='CLIENTE PEDIDO'!I24 | H24: ='CLIENTE PEDIDO'!M24 | I24: ='CLIENTE PEDIDO'!O24
H25: TOTAL B.I. | I25: =SUM(I10:I24) -> 585.772
H26: I.V.A. (21%) | I26: =I25*0.21 -> 123.01212
I27: =I25+I26 -> 708.78412
A29: Michael Leffler | B29: Peones Camineros, Portal A 2 izq. 11158. La barca de Vejer
A30: X-0000000000-W | C30: 600 100 100 | E30: pedidos@wepp.es
A31: CCC | B31: 2100 1789 0100 0000 0001

Sheet FACTURA COMERCIAL
A1: DATOS COMERCIAL
A2: Razón Social:
A3: CIF:
A4: Dirección:
A5: Dirección envío:
A6: Teléfono:
A7: Correo Electrónico:
A8: FACTURA | G8: Nº | H8: 2025-1
A9: Descripción | B9: Ref. | C9: Volumen | D9: Cantidad | E9: Unidad | F9: Total | G9: Precio ud | H9: Dto(%) | I9: ocultar | J9: B.I.
A10: ='CLIENTE PEDIDO'!B10 -> Limpiador de Motor SF (sin disolventes) | B10: ='CLIENTE PEDIDO'!C10 -> 2010 SF | C10: ='CLIENTE PEDIDO'!D10 -> 300 ml | D10: =IF(A10="-","",'CLIENTE PEDIDO'!E10) -> unidad | E10: =IF(A10="-","",'CLIENTE PEDIDO'!F10) -> 12 | F10: ='CLIENTE PEDIDO'!H10 -> 12 | G10: =IF(A10="-","",VLOOKUP(A10,DATOS!$I$3:$W$138,15,FALSE)) -> 2.2 | H10: =IF(A10="-","",('CLIENTE PEDIDO'!M10)/2) -> 2.5 | I10: =(100-H10)/100 -> 0.975 | J10: =IF(A10="-","",F10*G10*I10) -> 25.74
A11: ='CLIENTE PEDIDO'!B11 -> Protector del Sistema de Refrigeración | B11: ='CLIENTE PEDIDO'!C11 -> 2020 | C11: ='CLIENTE PEDIDO'!D11 -> 300 ml | D11: =IF(A11="-","",'CLIENTE PEDIDO'!E11) -> caja | E11: =IF(A11="-","",'CLIENTE PEDIDO'!F11) -> 1 | F11: ='CLIENTE PEDIDO'!H11 -> 24 | G11: =IF(A11="-","",VLOOKUP(A11,DATOS!$I$3:$W$138,15,FALSE)) -> 1.4 | H11: =IF(A11="-","",('CLIENTE PEDIDO'!M11)/2) -> 7.5 | I11: ='CLIENTE PEDIDO'!N11 -> 0.85 | J11: =IF(A11="-","",F11*G11*I11) -> 28.56
A12: ='CLIENTE PEDIDO'!B12 -> Airfresh Menta | B12: ='CLIENTE PEDIDO'!C12 -> 2125 | C12: ='CLIENTE PEDIDO'!D12 -> 100 ml | D12: =IF(A12="-","",'CLIENTE PEDIDO'!E12) -> caja | E12: =IF(A12="-","",'CLIENTE PEDIDO'!F12) -> 1 | F12: ='CLIENTE PEDIDO'!H12 -> 24 | G12: =IF(A12="-","",VLOOKUP(A12,DATOS!$I$3:$W$138,15,FALSE)) -> 2 | H12: =IF(A12="-","",('CLIENTE PEDIDO'!M12)/2) -> 7.5 | I12: ='CLIENTE PEDIDO'!N12 -> 0.85 | J12: =IF(A12="-","",F12*G12*I12) -> 40.8
A13: ='CLIENTE PEDIDO'!B13 -> Limpiador Intensivo Diésel | B13: ='CLIENTE PEDIDO'!C13 -> 2030 | C13: ='CLIENTE PEDIDO'!D13 -> 500 ml | D13: =IF(A13="-","",'CLIENTE PEDIDO'!E13) -> unidad | E13: =IF(A13="-","",'CLIENTE PEDIDO'!F13) -> 3 | F13: ='CLIENTE PEDIDO'!H13 -> 3 | G13: =IF(A13="-","",VLOOKUP(A13,DATOS!$I$3:$W$138,15,FALSE)) -> 1.8 | H13: =IF(A13="-","",('CLIENTE PEDIDO'!M13)/2) -> 0 | I13: ='CLIENTE PEDIDO'!N13 -> 1 | J13: =IF(A13="-","",F13*G13*I13) -> 5.4
A14: ='CLIENTE PEDIDO'!B14 -> Frenos Hi Tec | B14: ='CLIENTE PEDIDO'!C14 -> 255 | C14: ='CLIENTE PEDIDO'!D14 -> 400 ml | D14: =IF(A14="-","",'CLIENTE PEDIDO'!E14) -> unidad | E14: =IF(A14="-","",'CLIENTE PEDIDO'!F14) -> 5 | F14: ='CLIENTE PEDIDO'!H14 -> 5 | G14: =IF(A14="-","",VLOOKUP(A14,DATOS!$I$3:$W$138,15,FALSE)) -> 2.38 | H14: =IF(A14="-","",('CLIENTE PEDIDO'!M14)/2) -> 0 | I14: ='CLIENTE PEDIDO'!N14 -> 1 | J14: =IF(A14="-","",F14*G14*I14) -> 11.9
A15: ='CLIENTE PEDIDO'!B15 -> - | B15: ='CLIENTE PEDIDO'!C15 | C15: ='CLIENTE PEDIDO'!D15 | D15: =IF(A15="-","",'CLIENTE PEDIDO'!E15) | E15: =IF(A15="-","",'CLIENTE PEDIDO'!F15) | F15: ='CLIENTE PEDIDO'!H15 | G15: =IF(A15="-","",VLOOKUP(A15,DATOS!$I$3:$W$138,15,FALSE)) | H15: =IF(A15="-","",('CLIENTE PEDIDO'!M15)/2) | I15: ='CLIENTE PEDIDO'!N15 | J15: =IF(A15="-","",F15*G15*I15)
A16: ='CLIENTE PEDIDO'!B16 -> - | B16: ='CLIENTE PEDIDO'!C16 | C16: ='CLIENTE PEDIDO'!D16 | D16: =IF(A16="-","",'CLIENTE PEDIDO'!E16) | E16: =IF(A16="-","",'CLIENTE PEDIDO'!F16) | F16: ='CLIENTE PEDIDO'!H16 | G16: =IF(A16="-","",VLOOKUP(A16,DATOS!$I$3:$W$138,15,FALSE)) | H16: =IF(A16="-","",('CLIENTE PEDIDO'!M16)/2) | I16: ='CLIENTE PEDIDO'!N16 | J16: =IF(A16="-","",F16*G16*I16)
A17: ='CLIENTE PEDIDO'!B17 -> - | B17: ='CLIENTE PEDIDO'!C17 | C17: ='CLIENTE PEDIDO'!D17 | D17: =IF(A17="-","",'CLIENTE PEDIDO'!E17) | E17: =IF(A17="-","",'CLIENTE PEDIDO'!F17) | F17: ='CLIENTE PEDIDO'!H17 | G17: =IF(A17="-","",VLOOKUP(A17,DATOS!$I$3:$W$138,15,FALSE)) | H17: =IF(A17="-","",('CLIENTE PEDIDO'!M17)/2) | I17: ='CLIENTE PEDIDO'!N17 | J17: =IF(A17="-","",F17*G17*I17)
A18: ='CLIENTE PEDIDO'!B18 -> - | B18: ='CLIENTE PEDIDO'!C18 | C18: ='CLIENTE PEDIDO'!D18 | D18: =IF(A18="-","",'CLIENTE PEDIDO'!E18) | E18: =IF(A18="-","",'CLIENTE PEDIDO'!F18) | F18: ='CLIENTE PEDIDO'!H18 | G18: =IF(A18="-","",VLOOKUP(A18,DATOS!$I$3:$W$138,15,FALSE)) | H18: =IF(A18="-","",('CLIENTE PEDIDO'!M18)/2) | I18: ='CLIENTE PEDIDO'!N18 | J18: =IF(A18="-","",F18*G18*I18)
A19: ='CLIENTE PEDIDO'!B19 -> - | B19: ='CLIENTE PEDIDO'!C19 | C19: ='CLIENTE PEDIDO'!D19 | D19: =IF(A19="-","",'CLIENTE PEDIDO'!E19) | E19: =IF(A19="-","",'CLIENTE PEDIDO'!F19) | F19: ='CLIENTE PEDIDO'!H19 | G19: =IF(A19="-","",VLOOKUP(A19,DATOS!$I$3:$W$138,15,FALSE)) | H19: =IF(A19="-","",('CLIENTE PEDIDO'!M19)/2) | I19: ='CLIENTE PEDIDO'!N19 | J19: =IF(A19="-","",F19*G19*I19)
A20: ='CLIENTE PEDIDO'!B20 -> - | B20: ='CLIENTE PEDIDO'!C20 | C20: ='CLIENTE PEDIDO'!D20 | D20: =IF(A20="-","",'CLIENTE PEDIDO'!E20) | E20: =IF(A20="-","",'CLIENTE PEDIDO'!F20) | F20: ='CLIENTE PEDIDO'!H20 | G20: =IF(A20="-","",VLOOKUP(A20,DATOS!$I$3:$W$138,15,FALSE)) | H20: =IF(A20="-","",('CLIENTE PEDIDO'!M20)/2) | I20: ='CLIENTE PEDIDO'!N20 | J20: =IF(A20="-","",F20*G20*I20)
A21: ='CLIENTE PEDIDO'!B21 -> - | B21: ='CLIENTE PEDIDO'!C21 | C21: ='CLIENTE PEDIDO'!D21 | D21: =IF(A21="-","",'CLIENTE PEDIDO'!E21) | E21: =IF(A21="-","",'CLIENTE PEDIDO'!F21) | F21: ='CLIENTE PEDIDO'!H21 | G21: =IF(A21="-","",VLOOKUP(A21,DATOS!$I$3:$W$138,15,FALSE)) | H21: =IF(A21="-","",('CLIENTE PEDIDO'!M21)/2) | I21: ='CLIENTE PEDIDO'!N21 | J21: =IF(A21="-","",F21*G21*I21)
A22: ='CLIENTE PEDIDO'!B22 -> - | B22: ='CLIENTE PEDIDO'!C22 | C22: ='CLIENTE PEDIDO'!D22 | D22: =IF(A22="-","",'CLIENTE PEDIDO'!E22) | E22: =IF(A22="-","",'CLIENTE PEDIDO'!F22) | F22: ='CLIENTE PEDIDO'!H22 | G22: =IF(A22="-","",VLOOKUP(A22,DATOS!$I$3:$W$138,15,FALSE)) | H22: =IF(A22="-","",('CLIENTE PEDIDO'!M22)/2) | I22: ='CLIENTE PEDIDO'!N22 | J22: =IF(A22="-","",F22*G22*I22)
... A24: ='CLIENTE PEDIDO'!B24 -> - | B24: ='CLIENTE PEDIDO'!C24 | C24: ='CLIENTE PEDIDO'!D24 | D24: =IF(A24="-","",'CLIENTE PEDIDO'!E24) | E24: =IF(A24="-","",'CLIENTE PEDIDO'!F24) | F24: ='CLIENTE PEDIDO'!H24 | G24: =IF(A24="-","",VLOOKUP(A24,DATOS!$I$3:$W$138,15,FALSE)) | H24: =IF(A24="-","",('CLIENTE PEDIDO'!M24)/2) | I24: ='CLIENTE PEDIDO'!N24 | J24: =IF(A24="-","",F24*G24*I24)
H25: ='CLIENTE FACTURA'!H25 -> TOTAL B.I. | J25: =SUM(J10:J24) -> 112.4
H26: ='CLIENTE FACTURA'!H26 -> I.V.A. (21%) | I26: 0.21 | J26: =J25*0.21 -> 23.604
J27: =J25+J26 -> 136.004
A29: Michael Leffler | B29: Peones Camineros, Portal A 2 izq. 11158. La barca de Vejer
A30: X-0000000000-W | C30: 600 100 100 | E30: pedidos@wepp.es
A31: CCC | B31: 2100 1789 0100 0000 0001

Sheet DATOS
A1: 1 | B1: 2 | E1: 3 | F1: 4 | G1: 5 | H1: 6 | I1: 7 | J1: 8 | K1: 9 | L1: 10 | M1: 11 | N1: 12 | O1: 13 | P1: 14 | Q1: 15 | R1: 16 | S1: 17 | T1: 18 | U1: 19 | V1: 20 | W1: 21 | X1: 22 | Y1: 23 | Z1: 24 | AB1: 25 | AC1: 26 | AD1: 27 | AE1: 28 | AF1: 29 | AG1: 30 | AH1: 31 | AI1: 32 | AJ1: 33 | AK1: 34 | AL1: 35 | AM1: 36
A2: proveedor | B2: documento | C2: clase | E2: relevancia | F2: referencia | H2: Aleman | I2: Español | J2: =F2 -> referencia | K2: =G2 -> 0 | L2: COSTO | M2: PORTE UD | N2: ADUANA | O2: EMBALAJE | P2: MANIPULACIÓN | Q2: COSTO REAL | R2: PRECIO TALLER | S2: PRECIO TALLER +10 | T2: PRECIO CLIENTE | U2: BENEFICIO TOTAL | V2: BENEFICIO MIO | W2: BENEFICIO COMERCIAL | X2: BENEFICIO % | Z2: unidad | AA2: cantidad minima | AB2: dto unidad | AC2: unidades caja | AD2: dto caja | AE2: Volumen (L) | AF2: PESO (Kg) | AG2: PESO CAJA (Kg) | AH2: AUXILIAR COSTO+TRANSPORTE | AI2: TRANSPORTE | AJ2: Pedido unidad | AK2: Pedido caja | AL2: Palet | AM2: Precio Pedido
A3: WEPP | B3: C | C3: 1 | D3: =IF(C3=1,"Motor y Transmisión",IF(C3=2,"Refrigeración",IF(C3=3,"Climatización",IF(C3=4,"Sistema de Combustión",IF(C3=5,"Frenos",IF(C3=6,"Mantenimiento y Cuidado",IF(C3=7,"Carrocería",""))))))) -> Motor y Transmisión | E3: 1 | F3: 2010 SF | G3: =AE3*1000 -> 300 | H3: Motor System Reiniger (Lösungsmittelfrei) | I3: Limpiador de Motor SF (sin disolventes) | J3: =F3 -> 2010 SF | K3: =G3 -> 300 | L3: 2.95 | M3: 0.3 | N3: 0 | O3: 0.3 | P3: 0.3 | Q3: =+L3+M3+N3+O3+P3 -> 3.85 | R3: 9.35 | S3: =R3*1.1 -> 10.285 | T3: 16.85 | U3: =R3-Q3 -> 5.5 | V3: =U3*0.6 -> 3.3 | W3: =U3*0.4 -> 2.2 | Z3: 1 | AA3: =INT(AC3/3) -> 8 | AB3: 5 | AC3: 24 | AD3: =IF(AC3=24,15,IF(AC3=12,10,0)) -> 15 | AE3: 0.3 | AF3: =AE3*1.1 -> 0.33 | AG3: =AF3*AC3 -> 7.92 | AI3: 1 | AK3: 2
A4: WEPP | B4: C | C4: 1 | D4: =IF(C4=1,"Motor y Transmisión",IF(C4=2,"Refrigeración",IF(C4=3,"Climatización",IF(C4=4,"Sistema de Combustión",IF(C4=5,"Frenos",IF(C4=6,"Mantenimiento y Cuidado",IF(C4=7,"Carrocería",""))))))) -> Motor y Transmisión | E4: 1 | F4: 2110 | G4: =AE4*1000 -> 300 | H4: Motor Intensiv Reiniger | I4: Limpiador Intensivo de Motor | J4: =F4 -> 2110 | K4: =G4 -> 300 | L4: 4.78 | M4: 0.3 | N4: 0 | O4: 0.3 | P4: 0.3 | Q4: =+L4+M4+N4+O4+P4 -> 5.68 | R4: 12.85 | S4: =R4*1.1 -> 14.135 | T4: 21.35 | U4: =R4-Q4 -> 7.17 | V4: =U4*0.6 -> 4.302 | W4: =U4*0.4 -> 2.868 | Z4: 1 | AA4: =INT(AC4/3) -> 8 | AB4: 5 | AC4: 24 | AD4: =IF(AC4=24,15,IF(AC4=12,10,0)) -> 15 | AE4: 0.3 | AF4: =AE4*1.1 -> 0.33 | AG4: =AF4*AC4 -> 7.92 | AI4: 2 | AK4: 2
A5: WEPP | B5: C | C5: 1 | D5: =IF(C5=1,"Motor y Transmisión",IF(C5=2,"Refrigeración",IF(C5=3,"Climatización",IF(C5=4,"Sistema de Combustión",IF(C5=5,"Frenos",IF(C5=6,"Mantenimiento y Cuidado",IF(C5=7,"Carrocería",""))))))) -> Motor y Transmisión | E5: 1 | F5: 2011 | G5: =AE5*1000 -> 400 | H5: Ölstopp Additiv | I5: Tapafugas de Aceite 400 | J5: =F5 -> 2011 | K5: =G5 -> 400 | L5: 3.3 | M5: 0.3 | N5: 0 | O5: 0.3 | P5: 0.3 | Q5: =+L5+M5+N5+O5+P5 -> 4.2 | R5: 9.7 | S5: =R5*1.1 -> 10.67 | T5: 14.4 | U5: =R5-Q5 -> 5.5 | V5: =U5*0.6 -> 3.3 | W5: =U5*0.4 -> 2.2 | Z5: 1 | AA5: =INT(AC5/3) -> 8 | AB5: 5 | AC5: 24 | AD5: =IF(AC5=24,15,IF(AC5=12,10,0)) -> 15 | AE5: 0.4 | AF5: =AE5*1.1 -> 0.44 | AG5: =AF5*AC5 -> 10.56 | AI5: 3 | AK5: 2
A6: WEPP | B6: C | C6: 1 | D6: =IF(C6=1,"Motor y Transmisión",IF(C6=2,"Refrigeración",IF(C6=3,"Climatización",IF(C6=4,"Sistema de Combustión",IF(C6=5,"Frenos",IF(C6=6,"Mantenimiento y Cuidado",IF(C6=7,"Carrocería",""))))))) -> Motor y Transmisión | E6: 1 | F6: 2011-300 | G6: =AE6*1000 -> 300 | H6: Ölstopp Additiv | I6: Tapafugas de Aceite 300 | J6: =F6 -> 2011-300 | K6: =G6 -> 300 | L6: 2.8 | M6: 0.3 | N6: 0 | O6: 0.3 | P6: 0.3 | Q6: =+L6+M6+N6+O6+P6 -> 3.7 | R6: 7.5 | S6: =R6*1.1 -> 8.25 | T6: 13.45 | U6: =R6-Q6 -> 3.8 | V6: =U6*0.6 -> 2.28 | W6: =U6*0.4 -> 1.52 | Z6: 1 | AA6: =INT(AC6/3) -> 8 | AB6: 5 | AC6: 24 | AD6: =IF(AC6=24,15,IF(AC6=12,10,0)) -> 15 | AE6: 0.3 | AF6: =AE6*1.1 -> 0.33 | AG6: =AF6*AC6 -> 7.92
A7: WEPP | B7: C | C7: 1 | D7: =IF(C7=1,"Motor y Transmisión",IF(C7=2,"Refrigeración",IF(C7=3,"Climatización",IF(C7=4,"Sistema de Combustión",IF(C7=5,"Frenos",IF(C7=6,"Mantenimiento y Cuidado",IF(C7=7,"Carrocería",""))))))) -> Motor y Transmisión | E7: 1 | F7: 2111 | G7: =AE7*1000 -> 300 | H7: Motor Verschleiss Schutz | I7: Protector Contra el Desgaste del Motor | J7: =F7 -> 2111 | K7: =G7 -> 300 | L7: 3.95 | M7: 0.3 | N7: 0 | O7: 0.3 | P7: 0.3 | Q7: =+L7+M7+N7+O7+P7 -> 4.85 | R7: 10.05 | S7: =R7*1.1 -> 11.055 | T7: 18.1 | U7: =R7-Q7 -> 5.2 | V7: =U7*0.6 -> 3.12 | W7: =U7*0.4 -> 2.08 | Z7: 1 | AA7: =INT(AC7/3) -> 8 | AB7: 5 | AC7: 24 | AD7: =IF(AC7=24,15,IF(AC7=12,10,0)) -> 15 | AE7: 0.3 | AF7: =AE7*1.1 -> 0.33 | AG7: =AF7*AC7 -> 7.92 | AI7: 4 | AK7: 2
